<robot name="iCub">
  <link name="root_link">
    <inertial>
      <origin xyz="0.02488209999999999 0.00010394699999999017 -0.04408060000000001" rpy="1.5707963267948961 0 -1.5707963267948961"/>
      <mass value="5.09143"/>
      <inertia ixx="0.0139679" ixy="-5.93488e-06" ixz="-1.55458e-05" iyy="0.0202112" iyz="-0.00170968" izz="0.0249124"/>
    </inertial>
    <visual>
      <origin xyz="-0.036399999999999995 0 0.032" rpy="1.5707963267948961 0 -1.5707963267948961"/>
      <geometry>
        <mesh filename="package://iRonCub-Mk1_v1/iRonCub/meshes/stl/sim_sea_2-5_root_link_prt.stl" scale="0.001 0.001 0.001"/>
      </geometry>
      <material name="green">
        <color rgba="0 1 0 1"/>
      </material>
    </visual>
    <collision>
      <origin xyz="-0.036399999999999995 0 0.032" rpy="1.5707963267948961 0 -1.5707963267948961"/>
      <geometry>
        <mesh filename="package://iRonCub-Mk1_v1/iRonCub/meshes/stl/sim_sea_2-5_root_link_prt.stl" scale="0.001 0.001 0.001"/>
      </geometry>
    </collision>
  </link>
  <link name="torso_1">
    <inertial>
      <origin xyz="0.027092135899999998 0.02914798 -0.00043979999999999714" rpy="0 0 0"/>
      <mass value="0.67144"/>
      <inertia ixx="0.00040911" ixy="-1.04522e-06" ixz="-1.02516e-06" iyy="0.000384141" iyz="6.50708e-06" izz="0.000299445"/>
    </inertial>
    <visual>
      <origin xyz="0.027046299809264998 0.03199999999999968 0.036400000000000286" rpy="0 0 0"/>
      <geometry>
        <mesh filename="package://iRonCub-Mk1_v1/iRonCub/meshes/stl/sim_sea_2-5_lap_belt_1_prt.stl" scale="0.001 0.001 0.001"/>
      </geometry>
      <material name="black">
        <color rgba="0 0 0 1"/>
      </material>
    </visual>
    <collision>
      <origin xyz="0.027046299809264998 0.03199999999999968 0.036400000000000286" rpy="0 0 0"/>
      <geometry>
        <mesh filename="package://iRonCub-Mk1_v1/iRonCub/meshes/stl/sim_sea_2-5_lap_belt_1_prt.stl" scale="0.001 0.001 0.001"/>
      </geometry>
    </collision>
  </link>
  <joint name="torso_pitch" type="revolute">
    <origin xyz="0 0.027046299999999992 0" rpy="1.5707963267948961 0 -1.5707963267948961"/>
    <axis xyz="1.0 0.0 0.0"/>
    <parent link="root_link"/>
    <child link="torso_1"/>
    <limit effort="50000" lower="-0.3490658503988659" upper="1.2217304763960306" velocity="50000"/>
    <dynamics damping="1.0" friction="0.0"/>
  </joint>
  <link name="torso_2">
    <inertial>
      <origin xyz="-0.00011350780926499999 0.036152500000000004 0.05709630000000001" rpy="0 0 0"/>
      <mass value="0.425685"/>
      <inertia ixx="0.000829234" ixy="2.37006e-08" ixz="9.25231e-08" iyy="0.000436517" iyz="-1.74814e-07" izz="0.000604802"/>
    </inertial>
    <visual>
      <origin xyz="0 0.1433 0.03865310000000001" rpy="0 0 0"/>
      <geometry>
        <mesh filename="package://iRonCub-Mk1_v1/iRonCub/meshes/stl/sim_sea_2-5_lap_belt_2_prt.stl" scale="0.001 0.001 0.001"/>
      </geometry>
      <material name="red">
        <color rgba="1 0 0 1"/>
      </material>
    </visual>
    <collision>
      <origin xyz="0 0.1433 0.03865310000000001" rpy="0 0 0"/>
      <geometry>
        <mesh filename="package://iRonCub-Mk1_v1/iRonCub/meshes/stl/sim_sea_2-5_lap_belt_2_prt.stl" scale="0.001 0.001 0.001"/>
      </geometry>
    </collision>
  </link>
  <joint name="torso_roll" type="revolute">
    <origin xyz="0.027046299809264998 0.032 -0.05734460000000001" rpy="0 0 0"/>
    <axis xyz="0.0 0.0 -1.0"/>
    <parent link="torso_1"/>
    <child link="torso_2"/>
    <limit effort="50000" lower="-0.5235987755982988" upper="0.5235987755982988" velocity="50000"/>
    <dynamics damping="1.0" friction="0.0"/>
  </joint>
  <link name="chest">
    <inertial>
      <origin xyz="0.001377000190735 0.072282 -0.07247350000000001" rpy="0 0 0"/>
      <mass value="11.145012"/>
      <inertia ixx="0.07673325787628221" ixy="-4.9700785660735805e-06" ixz="-0.0005534129819303116" iyy="0.1006048939280262" iyz="0.0032829991782168137" izz="0.08648421058734253"/>
    </inertial>
    <visual>
      <origin xyz="0 0.07529999999999999 -0.024189000000000002" rpy="0 0 0"/>
      <geometry>
        <mesh filename="package://iRonCub-Mk1_v1/iRonCub/meshes/stl/sim_sea_2-5_chest_bb_prt.stl" scale="0.001 0.001 0.001"/>
      </geometry>
      <material name="blue">
        <color rgba="0 0 1 1"/>
      </material>
    </visual>
    <collision>
      <origin xyz="0 0.07529999999999999 -0.024189000000000002" rpy="0 0 0"/>
      <geometry>
        <mesh filename="package://iRonCub-Mk1_v1/iRonCub/meshes/stl/sim_sea_2-5_chest_bb_prt.stl" scale="0.001 0.001 0.001"/>
      </geometry>
    </collision>
  </link>
  <joint name="torso_yaw" type="revolute">
    <origin xyz="0 0.05 0.06284210000000001" rpy="0 0 0"/>
    <axis xyz="0.0 -1.0 0.0"/>
    <parent link="torso_2"/>
    <child link="chest"/>
    <limit effort="50000" lower="-0.8726646259971648" upper="0.8726646259971648" velocity="50000"/>
    <dynamics damping="1.0" friction="0.0"/>
  </joint>
  <link name="chest_realsense_frame"/>
  <joint name="chest_realsense_frame_fixed_joint" type="fixed">
    <origin xyz="0.008750000190735002 0.08155 0.09626100000000001" rpy="3.141592653589793 0 3.141592653589793"/>
    <parent link="chest"/>
    <child link="chest_realsense_frame"/>
    <dynamics damping="0.1"/>
  </joint>
  <link name="neck_1">
    <inertial>
      <origin xyz="7.056099073300001e-05 0.0065671471121877545 -0.006384087293175439" rpy="0 0 0"/>
      <mass value="0.125793"/>
      <inertia ixx="0.01" ixy="8.09156e-08" ixz="-3.74998e-08" iyy="0.01" iyz="9.39717e-06" izz="0.01"/>
    </inertial>
    <visual>
      <origin xyz="0 -0.07999699684365266 -0.029500669354382964" rpy="0 0 0"/>
      <geometry>
        <mesh filename="package://iRonCub-Mk1_v1/iRonCub/meshes/stl/sim_sea_2-5_neck_1_prt.stl" scale="0.001 0.001 0.001"/>
      </geometry>
      <material name="yellow">
        <color rgba="1 1 0 1"/>
      </material>
    </visual>
    <collision>
      <origin xyz="0 -0.07999699684365266 -0.029500669354382964" rpy="0 0 0"/>
      <geometry>
        <mesh filename="package://iRonCub-Mk1_v1/iRonCub/meshes/stl/sim_sea_2-5_neck_1_prt.stl" scale="0.001 0.001 0.001"/>
      </geometry>
    </collision>
  </link>
  <joint name="neck_pitch" type="revolute">
    <origin xyz="0 0.1553 0.0053103000000000004" rpy="-0.009686581894851408 0 0"/>
    <axis xyz="-1.0 0.0 0.0"/>
    <parent link="chest"/>
    <child link="neck_1"/>
    <limit effort="50000" lower="-0.6981317007977318" upper="0.3839724354387525" velocity="50000"/>
    <dynamics damping="1.0" friction="0.0"/>
  </joint>
  <link name="neck_2">
    <inertial>
      <origin xyz="-8.8573009265e-05 0.0352249762944902 -0.019545252675373756" rpy="0 0 0"/>
      <mass value="0.177087"/>
      <inertia ixx="0.01" ixy="-5.25591e-07" ixz="4.68307e-07" iyy="0.01" iyz="9.81476e-06" izz="0.01"/>
    </inertial>
    <visual>
      <origin xyz="0 -0.08949696442339733 -0.05030070595399978" rpy="0 0 0"/>
      <geometry>
        <mesh filename="package://iRonCub-Mk1_v1/iRonCub/meshes/stl/sim_sea_2-5_neck_2_prt.stl" scale="0.001 0.001 0.001"/>
      </geometry>
      <material name="pink">
        <color rgba="1 0 1 1"/>
      </material>
    </visual>
    <collision>
      <origin xyz="0 -0.08949696442339733 -0.05030070595399978" rpy="0 0 0"/>
      <geometry>
        <mesh filename="package://iRonCub-Mk1_v1/iRonCub/meshes/stl/sim_sea_2-5_neck_2_prt.stl" scale="0.001 0.001 0.001"/>
      </geometry>
    </collision>
  </link>
  <joint name="neck_roll" type="revolute">
    <origin xyz="0 0.009499967579744667 0.020800036599616822" rpy="0 0 0"/>
    <axis xyz="0.0 4.137773574602638e-10 0.9999999145675688"/>
    <parent link="neck_1"/>
    <child link="neck_2"/>
    <limit effort="50000" lower="-0.3490658503988659" upper="0.3490658503988659" velocity="50000"/>
    <dynamics damping="1.0" friction="0.0"/>
  </joint>
  <link name="head">
    <inertial>
      <origin xyz="-0.000574157809265 0.1135103526786149 -0.007539143563195377" rpy="0 0 0"/>
      <mass value="1.50691"/>
      <inertia ixx="0.00680478" ixy="-1.60267e-05" ixz="7.28166e-05" iyy="0.00634736" iyz="0.000292091" izz="0.00478116"/>
    </inertial>
    <visual>
      <origin xyz="0 -0.06715339437550044 -0.029500660692406613" rpy="0 0 0"/>
      <geometry>
        <mesh filename="package://iRonCub-Mk1_v1/iRonCub/meshes/stl/sim_sea_2-5_head_prt.stl" scale="0.001 0.001 0.001"/>
      </geometry>
      <material name="cyan">
        <color rgba="0 1 1 1"/>
      </material>
    </visual>
    <collision>
      <origin xyz="0 -0.06715339437550044 -0.029500660692406613" rpy="0 0 0"/>
      <geometry>
        <mesh filename="package://iRonCub-Mk1_v1/iRonCub/meshes/stl/sim_sea_2-5_head_prt.stl" scale="0.001 0.001 0.001"/>
      </geometry>
    </collision>
  </link>
  <joint name="neck_yaw" type="revolute">
    <origin xyz="0 -0.022343570047896888 -0.020800045261593174" rpy="0 0 0"/>
    <axis xyz="0.0 0.9999999145675688 -4.137773584856026e-10"/>
    <parent link="neck_2"/>
    <child link="head"/>
    <limit effort="50000" lower="-0.8726646259971648" upper="0.8726646259971648" velocity="50000"/>
    <dynamics damping="1.0" friction="0.0"/>
  </joint>
  <link name="imu_frame"/>
  <joint name="imu_frame_fixed_joint" type="fixed">
    <origin xyz="0.009500000190735 0.1334431763902131 0.009300024348917928" rpy="3.141592653589793 1.5707962417722505 -1.5707963254890998"/>
    <parent link="head"/>
    <child link="imu_frame"/>
    <dynamics damping="0.1"/>
  </joint>
  <link name="chest_r_jet_turbine">
    <inertial>
      <origin xyz="-8.301234271771568e-05 1.3339860153005478e-05 -0.16112279999999715" rpy="-1.570796323266716 0 -2.199113213812311"/>
      <mass value="1.91345"/>
      <inertia ixx="0.00734206" ixy="-2.05268e-06" ixz="8.57819e-06" iyy="0.00348075" iyz="1.1913e-05" izz="0.00733956"/>
    </inertial>
    <visual>
      <origin xyz="-0.025736724487065925 -0.1914325464069343 -0.18940009848002604" rpy="-1.570796323266716 0 -2.199113213812311"/>
      <geometry>
        <mesh filename="package://iRonCub-Mk1_v1/iRonCub/meshes/stl/sim_sea_2-5_r_p220_prt.stl" scale="0.001 0.001 0.001"/>
      </geometry>
      <material name="green">
        <color rgba="0 1 0 1"/>
      </material>
    </visual>
    <collision>
      <origin xyz="-0.025736724487065925 -0.1914325464069343 -0.18940009848002604" rpy="-1.570796323266716 0 -2.199113213812311"/>
      <geometry>
        <mesh filename="package://iRonCub-Mk1_v1/iRonCub/meshes/stl/sim_sea_2-5_r_p220_prt.stl" scale="0.001 0.001 0.001"/>
      </geometry>
    </collision>
  </link>
  <joint name="r_jet_turbine" type="fixed">
    <origin xyz="-0.169999999809265 -0.1141001 -0.1158885" rpy="-1.5707963207923834 -0.942479439777482 -3.141592651408043"/>
    <parent link="chest"/>
    <child link="chest_r_jet_turbine"/>
    <dynamics damping="0.1"/>
  </joint>
  <link name="chest_l_jet_turbine">
    <inertial>
      <origin xyz="-8.222821810605074e-05 1.3286115671029552e-05 -0.16112279999999773" rpy="-1.5707963232666984 0 -2.1991142623840707"/>
      <mass value="1.91345"/>
      <inertia ixx="0.00734206" ixy="-2.05268e-06" ixz="8.57819e-06" iyy="0.00348075" iyz="1.1913e-05" izz="0.00733956"/>
    </inertial>
    <visual>
      <origin xyz="-0.02573610258241668 -0.19143293014767443 -0.1894000984800243" rpy="-1.5707963232666984 0 -2.1991142623840707"/>
      <geometry>
        <mesh filename="package://iRonCub-Mk1_v1/iRonCub/meshes/stl/sim_sea_2-5_l_p220_prt.stl" scale="0.001 0.001 0.001"/>
      </geometry>
      <material name="white">
        <color rgba="1 1 1 1"/>
      </material>
    </visual>
    <collision>
      <origin xyz="-0.02573610258241668 -0.19143293014767443 -0.1894000984800243" rpy="-1.5707963232666984 0 -2.1991142623840707"/>
      <geometry>
        <mesh filename="package://iRonCub-Mk1_v1/iRonCub/meshes/stl/sim_sea_2-5_l_p220_prt.stl" scale="0.001 0.001 0.001"/>
      </geometry>
    </collision>
  </link>
  <joint name="l_jet_turbine" type="fixed">
    <origin xyz="0.17000000019073502 -0.1141001 -0.1158885" rpy="1.5707963294190979 1.3264512049591681 0"/>
    <parent link="chest"/>
    <child link="chest_l_jet_turbine"/>
    <dynamics damping="0.1"/>
  </joint>
  <link name="l_shoulder_1">
    <inertial>
      <origin xyz="0.012265033463409528 -3.300011353971066e-05 -0.0032056591871175155" rpy="0 0 0"/>
      <mass value="0.114882"/>
      <inertia ixx="0.01" ixy="-1.77064e-08" ixz="3.55951e-06" iyy="0.01" iyz="6.57597e-08" izz="0.01"/>
    </inertial>
    <visual>
      <origin xyz="-0.09900705928224206 0 -0.026528748755708542" rpy="0 0 0"/>
      <geometry>
        <mesh filename="package://iRonCub-Mk1_v1/iRonCub/meshes/stl/sim_sea_2-5_l_shoulder_1_prt.stl" scale="0.001 0.001 0.001"/>
      </geometry>
      <material name="dblue">
        <color rgba="0 0 0.8 1"/>
      </material>
    </visual>
    <collision>
      <origin xyz="-0.09900705928224206 0 -0.026528748755708542" rpy="0 0 0"/>
      <geometry>
        <mesh filename="package://iRonCub-Mk1_v1/iRonCub/meshes/stl/sim_sea_2-5_l_shoulder_1_prt.stl" scale="0.001 0.001 0.001"/>
      </geometry>
    </collision>
  </link>
  <joint name="l_shoulder_pitch" type="revolute">
    <origin xyz="0.120258000190735 0.07529999999999999 0.008034" rpy="0 0.523598883792035 -3.141592648178681"/>
    <axis xyz="-0.9659259261732691 -7.758694154976075e-15 -0.25881927552505174"/>
    <parent link="chest"/>
    <child link="l_shoulder_1"/>
    <limit effort="50000" lower="-1.6667894356545847" upper="0.17453292519943295" velocity="50000"/>
    <dynamics damping="1.0" friction="0.0"/>
  </joint>
  <link name="l_shoulder_2">
    <inertial>
      <origin xyz="0.021473511153041913 0.00026800955971750806 -0.019406690705168747" rpy="0 0 0"/>
      <mass value="0.238162"/>
      <inertia ixx="0.01" ixy="1.19701e-07" ixz="-1.29687e-05" iyy="0.01" iyz="1.20112e-06" izz="0.01"/>
    </inertial>
    <visual>
      <origin xyz="-0.1065877085675622 1.2838942596571368e-07 -0.040739585322631236" rpy="0 0 0"/>
      <geometry>
        <mesh filename="package://iRonCub-Mk1_v1/iRonCub/meshes/stl/sim_sea_2-5_l_shoulder_2_prt.stl" scale="0.001 0.001 0.001"/>
      </geometry>
      <material name="dgreen">
        <color rgba="0.1 0.8 0.1 1"/>
      </material>
    </visual>
    <collision>
      <origin xyz="-0.1065877085675622 1.2838942596571368e-07 -0.040739585322631236" rpy="0 0 0"/>
      <geometry>
        <mesh filename="package://iRonCub-Mk1_v1/iRonCub/meshes/stl/sim_sea_2-5_l_shoulder_2_prt.stl" scale="0.001 0.001 0.001"/>
      </geometry>
    </collision>
  </link>
  <joint name="l_shoulder_roll" type="revolute">
    <origin xyz="0.007580265732236205 0 0.014210592774007907" rpy="-0.2705976128330147 0.25268017210070187 1.5015567953707367"/>
    <axis xyz="-0.2588190174889569 -1.1253323287226445e-17 0.9659259953138497"/>
    <parent link="l_shoulder_1"/>
    <child link="l_shoulder_2"/>
    <limit effort="50000" lower="0.0" upper="2.8064894372068823" velocity="50000"/>
    <dynamics damping="1.0" friction="0.0"/>
  </joint>
  <link name="l_shoulder_3">
    <inertial>
      <origin xyz="0.026798412222098347 -1.5999862032878287e-05 0.014695680617749722" rpy="0 0 0"/>
      <mass value="0.35913"/>
      <inertia ixx="0.01" ixy="-2.22441e-07" ixz="-4.95846e-05" iyy="0.01" iyz="1.07538e-07" izz="0.01"/>
    </inertial>
    <visual>
      <origin xyz="-0.13190103768539627 0 -0.03534276691935262" rpy="0 0 0"/>
      <geometry>
        <mesh filename="package://iRonCub-Mk1_v1/iRonCub/meshes/stl/sim_sea_2-5_l_upper_arm_prt.stl" scale="0.001 0.001 0.001"/>
      </geometry>
      <material name="gray">
        <color rgba="0.5 0.5 0.5 1"/>
      </material>
    </visual>
    <collision>
      <origin xyz="-0.13190103768539627 0 -0.03534276691935262" rpy="0 0 0"/>
      <geometry>
        <mesh filename="package://iRonCub-Mk1_v1/iRonCub/meshes/stl/sim_sea_2-5_l_upper_arm_prt.stl" scale="0.001 0.001 0.001"/>
      </geometry>
    </collision>
  </link>
  <joint name="l_shoulder_yaw" type="revolute">
    <origin xyz="0.025313329844247154 1.2922216940935982e-07 -0.005396821114290115" rpy="-0.2526895449300475 -0.00851861944328215 -0.06703989350790952"/>
    <axis xyz="0.9659258393523111 -1.3021471243345694e-15 0.258818996349831"/>
    <parent link="l_shoulder_2"/>
    <child link="l_shoulder_3"/>
    <limit effort="50000" lower="-0.6457718232379019" upper="1.3962634015954636" velocity="50000"/>
    <dynamics damping="1.0" friction="0.0"/>
  </joint>
  <link name="l_upper_arm">
    <inertial>
      <origin xyz="-0.0031401005252317364 -0.0005800001394788146 0.030014099942354502" rpy="0 -1.3089969894682452 -3.1415926535897842"/>
      <mass value="0.713864"/>
      <inertia ixx="0.000455006" ixy="-9.1018e-07" ixz="-3.2008e-05" iyy="0.000615652" iyz="1.30798e-05" izz="0.000613922"/>
    </inertial>
    <visual>
      <origin xyz="-0.014921196617346701 -1.2999101713692673e-05 -0.19330000026117394" rpy="0 -1.3089969894682452 -3.1415926535897842"/>
      <geometry>
        <mesh filename="package://iRonCub-Mk1_v1/iRonCub/meshes/stl/sim_sea_2-5_l_elbow_prt.stl" scale="0.001 0.001 0.001"/>
      </geometry>
      <material name="green">
        <color rgba="0 1 0 1"/>
      </material>
    </visual>
    <collision>
      <origin xyz="-0.014921196617346701 -1.2999101713692673e-05 -0.19330000026117394" rpy="0 -1.3089969894682452 -3.1415926535897842"/>
      <geometry>
        <mesh filename="package://iRonCub-Mk1_v1/iRonCub/meshes/stl/sim_sea_2-5_l_elbow_prt.stl" scale="0.001 0.001 0.001"/>
      </geometry>
    </collision>
  </link>
  <joint name="l_arm_ft_sensor" type="fixed">
    <origin xyz="0.050930143245201204 0 0.029175829465900135" rpy="0 -1.3089969894682456 3.1415926535897762"/>
    <parent link="l_shoulder_3"/>
    <child link="l_upper_arm"/>
    <dynamics damping="0.1"/>
  </joint>
  <link name="l_elbow_1">
    <inertial>
      <origin xyz="0.08009498249093802 -0.010598999625261854 0.012646624691198663" rpy="0 0 0"/>
      <mass value="0.851196"/>
      <inertia ixx="0.01" ixy="-0.000415641" ixz="-0.000600892" iyy="0.01" iyz="-0.000277573" izz="0.01"/>
    </inertial>
    <visual>
      <origin xyz="-0.25941085816250975 -0.01998700126661604 -0.08495647371565368" rpy="0 0 0"/>
      <geometry>
        <mesh filename="package://iRonCub-Mk1_v1/iRonCub/meshes/stl/sim_sea_2-5_l_elbow_prosup_prt.stl" scale="0.001 0.001 0.001"/>
      </geometry>
      <material name="black">
        <color rgba="0 0 0 1"/>
      </material>
    </visual>
    <collision>
      <origin xyz="-0.25941085816250975 -0.01998700126661604 -0.08495647371565368" rpy="0 0 0"/>
      <geometry>
        <mesh filename="package://iRonCub-Mk1_v1/iRonCub/meshes/stl/sim_sea_2-5_l_elbow_prosup_prt.stl" scale="0.001 0.001 0.001"/>
      </geometry>
    </collision>
  </link>
  <joint name="l_elbow" type="revolute">
    <origin xyz="0 -0.02000000036832994 0.0792599999070578" rpy="0 -1.3089969894682456 -3.141592653589785"/>
    <axis xyz="-2.50779604241262e-15 -1.0 4.536843798859691e-15"/>
    <parent link="l_upper_arm"/>
    <child link="l_elbow_1"/>
    <limit effort="50000" lower="0.2617993877991494" upper="1.8500490071139892" velocity="50000"/>
    <dynamics damping="1.0" friction="0.0"/>
  </joint>
  <link name="l_arm_jet_turbine">
    <inertial>
      <origin xyz="0.00010960403737868621 -2.0526052205815937e-05 -0.11384200000174005" rpy="0 -1.3089969894683429 0.08726612152045043"/>
      <mass value="1.114"/>
      <inertia ixx="0.00134589" ixy="-1.06448e-06" ixz="-0.000328072" iyy="0.00256" iyz="1.00102e-07" izz="0.00246242"/>
    </inertial>
    <visual>
      <origin xyz="0.04580644795731287 -0.0655260674436383 -0.5061700003766975" rpy="0 -1.3089969894683429 0.08726612152045043"/>
      <geometry>
        <mesh filename="package://iRonCub-Mk1_v1/iRonCub/meshes/stl/sim_sea_2-5_l_elbow_p100_prt.stl" scale="0.001 0.001 0.001"/>
      </geometry>
      <material name="red">
        <color rgba="1 0 0 1"/>
      </material>
    </visual>
    <collision>
      <origin xyz="0.04580644795731287 -0.0655260674436383 -0.5061700003766975" rpy="0 -1.3089969894683429 0.08726612152045043"/>
      <geometry>
        <mesh filename="package://iRonCub-Mk1_v1/iRonCub/meshes/stl/sim_sea_2-5_l_elbow_p100_prt.stl" scale="0.001 0.001 0.001"/>
      </geometry>
    </collision>
  </link>
  <joint name="l_elbow_turbine" type="fixed">
    <origin xyz="0.21917946168178 0.04928200108561118 0.08461084782628614" rpy="-0.31447469072215356 1.2951527191646701 -0.32597066124451773"/>
    <parent link="l_elbow_1"/>
    <child link="l_arm_jet_turbine"/>
    <dynamics damping="0.1"/>
  </joint>
  <link name="r_shoulder_1">
    <inertial>
      <origin xyz="-0.012266467438645498 3.200000000000425e-05 -0.0032101429043969038" rpy="0 0 0"/>
      <mass value="0.114862"/>
      <inertia ixx="0.01" ixy="-1.65173e-08" ixz="-3.55626e-06" iyy="0.01" iyz="-6.13337e-08" izz="0.01"/>
    </inertial>
    <visual>
      <origin xyz="0.09900705928224204 0 -0.026528748755708542" rpy="0 0 0"/>
      <geometry>
        <mesh filename="package://iRonCub-Mk1_v1/iRonCub/meshes/stl/sim_sea_2-5_r_shoulder_1_prt.stl" scale="0.001 0.001 0.001"/>
      </geometry>
      <material name="blue">
        <color rgba="0 0 1 1"/>
      </material>
    </visual>
    <collision>
      <origin xyz="0.09900705928224204 0 -0.026528748755708542" rpy="0 0 0"/>
      <geometry>
        <mesh filename="package://iRonCub-Mk1_v1/iRonCub/meshes/stl/sim_sea_2-5_r_shoulder_1_prt.stl" scale="0.001 0.001 0.001"/>
      </geometry>
    </collision>
  </link>
  <joint name="r_shoulder_pitch" type="revolute">
    <origin xyz="-0.120257999809265 0.07529999999999999 0.008034" rpy="0 -0.523598883792035 3.141592653589793"/>
    <axis xyz="-0.965925926173269 0.0 0.25881927552505174"/>
    <parent link="chest"/>
    <child link="r_shoulder_1"/>
    <limit effort="50000" lower="-1.6667894356545847" upper="0.17453292519943295" velocity="50000"/>
    <dynamics damping="1.0" friction="0.0"/>
  </joint>
  <link name="r_shoulder_2">
    <inertial>
      <origin xyz="-0.021414170943809915 0.00027172527255132917 -0.019440234453461297" rpy="0 0 0"/>
      <mass value="0.238162"/>
      <inertia ixx="0.01" ixy="-1.12091e-07" ixz="1.02574e-05" iyy="0.01" iyz="1.19785e-06" izz="0.01"/>
    </inertial>
    <visual>
      <origin xyz="0.10658780856753212 2.3191471541783582e-07 -0.040739212117532925" rpy="0 0 0"/>
      <geometry>
        <mesh filename="package://iRonCub-Mk1_v1/iRonCub/meshes/stl/sim_sea_2-5_r_shoulder_2_prt.stl" scale="0.001 0.001 0.001"/>
      </geometry>
      <material name="yellow">
        <color rgba="1 1 0 1"/>
      </material>
    </visual>
    <collision>
      <origin xyz="0.10658780856753212 2.3191471541783582e-07 -0.040739212117532925" rpy="0 0 0"/>
      <geometry>
        <mesh filename="package://iRonCub-Mk1_v1/iRonCub/meshes/stl/sim_sea_2-5_r_shoulder_2_prt.stl" scale="0.001 0.001 0.001"/>
      </geometry>
    </collision>
  </link>
  <joint name="r_shoulder_roll" type="revolute">
    <origin xyz="-0.007580465732273681 0 0.014210246363868029" rpy="-0.2705976115829963 -0.252680154648383 -1.5015568003498745"/>
    <axis xyz="-0.258819 -2.0285226262510233e-17 -0.965926"/>
    <parent link="r_shoulder_1"/>
    <child link="r_shoulder_2"/>
    <limit effort="50000" lower="0.0" upper="2.8064894372068823" velocity="50000"/>
    <dynamics damping="1.0" friction="0.0"/>
  </joint>
  <link name="r_shoulder_3">
    <inertial>
      <origin xyz="-0.02676207668711196 -6.999999999979245e-06 0.014699920771321831" rpy="0 0 0"/>
      <mass value="0.35913"/>
      <inertia ixx="0.01" ixy="3.60361e-07" ixz="4.94445e-05" iyy="0.01" iyz="2.65919e-07" izz="0.01"/>
    </inertial>
    <visual>
      <origin xyz="0.13193387916408805 0 -0.03535156676465448" rpy="0 0 0"/>
      <geometry>
        <mesh filename="package://iRonCub-Mk1_v1/iRonCub/meshes/stl/sim_sea_2-5_r_upper_arm_prt.stl" scale="0.001 0.001 0.001"/>
      </geometry>
      <material name="pink">
        <color rgba="1 0 1 1"/>
      </material>
    </visual>
    <collision>
      <origin xyz="0.13193387916408805 0 -0.03535156676465448" rpy="0 0 0"/>
      <geometry>
        <mesh filename="package://iRonCub-Mk1_v1/iRonCub/meshes/stl/sim_sea_2-5_r_upper_arm_prt.stl" scale="0.001 0.001 0.001"/>
      </geometry>
    </collision>
  </link>
  <joint name="r_shoulder_yaw" type="revolute">
    <origin xyz="-0.025346071323150032 2.3275042729253848e-07 -0.005387648064565639" rpy="-0.2526895461750575 0.008518618321396994 0.06703988914196896"/>
    <axis xyz="0.9659258438815126 -2.220446049250313e-16 -0.2588189794466167"/>
    <parent link="r_shoulder_2"/>
    <child link="r_shoulder_3"/>
    <limit effort="50000" lower="-0.6457718232379019" upper="1.3962634015954636" velocity="50000"/>
    <dynamics damping="1.0" friction="0.0"/>
  </joint>
  <link name="r_upper_arm">
    <inertial>
      <origin xyz="-0.003128599999999997 0.0005970000000000003 0.03000619999999999" rpy="0 1.30899700696774 0"/>
      <mass value="0.713703"/>
      <inertia ixx="0.000454597" ixy="-9.33213e-08" ixz="3.20152e-05" iyy="0.000614158" iyz="1.14372e-05" izz="0.000612647"/>
    </inertial>
    <visual>
      <origin xyz="-0.014921199999999996 -1.3999999999944612e-05 -0.19329999999999997" rpy="0 1.30899700696774 0"/>
      <geometry>
        <mesh filename="package://iRonCub-Mk1_v1/iRonCub/meshes/stl/sim_sea_2-5_r_elbow_prt.stl" scale="0.001 0.001 0.001"/>
      </geometry>
      <material name="cyan">
        <color rgba="0 1 1 1"/>
      </material>
    </visual>
    <collision>
      <origin xyz="-0.014921199999999996 -1.3999999999944612e-05 -0.19329999999999997" rpy="0 1.30899700696774 0"/>
      <geometry>
        <mesh filename="package://iRonCub-Mk1_v1/iRonCub/meshes/stl/sim_sea_2-5_r_elbow_prt.stl" scale="0.001 0.001 0.001"/>
      </geometry>
    </collision>
  </link>
  <joint name="r_arm_ft_sensor" type="fixed">
    <origin xyz="-0.0508973017665091 0 0.029167029620599215" rpy="0 -1.3089970069677397 0"/>
    <parent link="r_shoulder_3"/>
    <child link="r_upper_arm"/>
    <dynamics damping="0.1"/>
  </joint>
  <link name="r_elbow_1">
    <inertial>
      <origin xyz="-0.0799107547366651 0.009468000000000032 0.012634841551304036" rpy="0 0 0"/>
      <mass value="0.846449"/>
      <inertia ixx="0.01" ixy="0.000417108" ixz="0.000600677" iyy="0.01" iyz="-0.000277665" izz="0.01"/>
    </inertial>
    <visual>
      <origin xyz="0.2594108582522262 0 -0.08495647373969467" rpy="0 0 0"/>
      <geometry>
        <mesh filename="package://iRonCub-Mk1_v1/iRonCub/meshes/stl/sim_sea_2-5_r_elbow_prosup_prt.stl" scale="0.001 0.001 0.001"/>
      </geometry>
      <material name="green">
        <color rgba="0 1 0 1"/>
      </material>
    </visual>
    <collision>
      <origin xyz="0.2594108582522262 0 -0.08495647373969467" rpy="0 0 0"/>
      <geometry>
        <mesh filename="package://iRonCub-Mk1_v1/iRonCub/meshes/stl/sim_sea_2-5_r_elbow_prosup_prt.stl" scale="0.001 0.001 0.001"/>
      </geometry>
    </collision>
  </link>
  <joint name="r_elbow" type="revolute">
    <origin xyz="0 -1.4000000000014001e-05 0.07925999999999998" rpy="0 1.3089970069677397 0"/>
    <axis xyz="2.220446049250313e-16 1.0000000000000002 0.0"/>
    <parent link="r_upper_arm"/>
    <child link="r_elbow_1"/>
    <limit effort="50000" lower="0.2617993877991494" upper="1.8500490071139892" velocity="50000"/>
    <dynamics damping="1.0" friction="0.0"/>
  </joint>
  <link name="r_arm_jet_turbine">
    <inertial>
      <origin xyz="0.00010984155626070358 -1.999377273191605e-05 -0.11384199999987513" rpy="0 1.308997002555593 1.1344643227498103"/>
      <mass value="1.114"/>
      <inertia ixx="0.00134298" ixy="5.63883e-06" ixz="0.00032383" iyy="0.00255407" iyz="2.42238e-06" izz="0.00247126"/>
    </inertial>
    <visual>
      <origin xyz="0.04593209742987085 -0.0654666332784982 -0.506170000176138" rpy="0 1.308997002555593 1.1344643227498103"/>
      <geometry>
        <mesh filename="package://iRonCub-Mk1_v1/iRonCub/meshes/stl/sim_sea_2-5_r_elbow_p100_prt.stl" scale="0.001 0.001 0.001"/>
      </geometry>
      <material name="white">
        <color rgba="1 1 1 1"/>
      </material>
    </visual>
    <collision>
      <origin xyz="0.04593209742987085 -0.0654666332784982 -0.506170000176138" rpy="0 1.308997002555593 1.1344643227498103"/>
      <geometry>
        <mesh filename="package://iRonCub-Mk1_v1/iRonCub/meshes/stl/sim_sea_2-5_r_elbow_p100_prt.stl" scale="0.001 0.001 0.001"/>
      </geometry>
    </collision>
  </link>
  <joint name="r_elbow_turbine" type="fixed">
    <origin xyz="-0.2191794619029947 0.06929600000000004 0.08461084788556195" rpy="1.2833359439264203 -0.42050074885941974 -1.4506880627041787"/>
    <parent link="r_elbow_1"/>
    <child link="r_arm_jet_turbine"/>
    <dynamics damping="0.1"/>
  </joint>
  <link name="l_hip_1">
    <inertial>
      <origin xyz="-0.0005107999999999918 0.03809229999999998 -8.299999999999974e-05" rpy="1.5707963267948961 0 1.5707963267948961"/>
      <mass value="0.919725"/>
      <inertia ixx="0.000404539" ixy="1.18502e-06" ixz="-9.64514e-07" iyy="0.000573315" iyz="-1.06028e-06" izz="0.000578982"/>
    </inertial>
    <visual>
      <origin xyz="0.04285150000005946 -0.025999999999999673 0.15191299999998345" rpy="1.5707963267948961 0 1.5707963267948961"/>
      <geometry>
        <mesh filename="package://iRonCub-Mk1_v1/iRonCub/meshes/stl/sim_sea_2-5_l_hip_1_prt.stl" scale="0.001 0.001 0.001"/>
      </geometry>
      <material name="dblue">
        <color rgba="0 0 0.8 1"/>
      </material>
    </visual>
    <collision>
      <origin xyz="0.04285150000005946 -0.025999999999999673 0.15191299999998345" rpy="1.5707963267948961 0 1.5707963267948961"/>
      <geometry>
        <mesh filename="package://iRonCub-Mk1_v1/iRonCub/meshes/stl/sim_sea_2-5_l_hip_1_prt.stl" scale="0.001 0.001 0.001"/>
      </geometry>
    </collision>
  </link>
  <joint name="l_hip_pitch" type="revolute">
    <origin xyz="0.006451499999999999 -0.026000000000000023 -0.11991299999999999" rpy="0 0 -3.141592653589793"/>
    <axis xyz="-2.220446049250313e-16 -0.9999999999999998 0.0"/>
    <parent link="root_link"/>
    <child link="l_hip_1"/>
    <limit effort="55.5" lower="-0.7853981633974483" upper="2.3387411976724017" velocity="5.1"/>
    <dynamics damping="1.0" friction="0.0"/>
  </joint>
  <link name="l_hip_2">
    <inertial>
      <origin xyz="-0.0011062999999999976 1.730000000001175e-05 -0.04457399999999995" rpy="1.5707963267948961 0 1.5707963267948961"/>
      <mass value="0.415987"/>
      <inertia ixx="0.000475741" ixy="2.89355e-07" ixz="-6.72876e-08" iyy="0.000279828" iyz="6.7417e-06" izz="0.000307828"/>
    </inertial>
    <visual>
      <origin xyz="0.04285149980932397 -0.07010000000000878 0.15191299999997981" rpy="1.5707963267948961 0 1.5707963267948961"/>
      <geometry>
        <mesh filename="package://iRonCub-Mk1_v1/iRonCub/meshes/stl/sim_sea_2-5_l_hip_2_prt.stl" scale="0.001 0.001 0.001"/>
      </geometry>
      <material name="dgreen">
        <color rgba="0.1 0.8 0.1 1"/>
      </material>
    </visual>
    <collision>
      <origin xyz="0.04285149980932397 -0.07010000000000878 0.15191299999997981" rpy="1.5707963267948961 0 1.5707963267948961"/>
      <geometry>
        <mesh filename="package://iRonCub-Mk1_v1/iRonCub/meshes/stl/sim_sea_2-5_l_hip_2_prt.stl" scale="0.001 0.001 0.001"/>
      </geometry>
    </collision>
  </link>
  <joint name="l_hip_roll" type="revolute">
    <origin xyz="0 0.044099999999999986 0" rpy="0 0 0"/>
    <axis xyz="0.9999999999999998 0.0 2.220446049250313e-16"/>
    <parent link="l_hip_1"/>
    <child link="l_hip_2"/>
    <limit effort="37.0" lower="-0.3490658503988659" upper="2.0943951023931953" velocity="7.64"/>
    <dynamics damping="1.0" friction="0.0"/>
  </joint>
  <link name="l_hip_3">
    <inertial>
      <origin xyz="-0.00012290000000000217 -0.0002822999999999992 0.008718000000000031" rpy="-1.5707963267948961 0 -1.5707963267948961"/>
      <mass value="0.126212"/>
      <inertia ixx="0.01" ixy="2.67901e-07" ixz="-4.41463e-09" iyy="0.01" iyz="3.32338e-08" izz="0.01"/>
    </inertial>
    <visual>
      <origin xyz="0.04370906139999997 0.07010002460000003 -0.22621299999998065" rpy="-1.5707963267948961 0 -1.5707963267948961"/>
      <geometry>
        <mesh filename="package://iRonCub-Mk1_v1/iRonCub/meshes/stl/sim_sea_2-5_l_upper_thigh_prt.stl" scale="0.001 0.001 0.001"/>
      </geometry>
      <material name="gray">
        <color rgba="0.5 0.5 0.5 1"/>
      </material>
    </visual>
    <collision>
      <origin xyz="0.04370906139999997 0.07010002460000003 -0.22621299999998065" rpy="-1.5707963267948961 0 -1.5707963267948961"/>
      <geometry>
        <mesh filename="package://iRonCub-Mk1_v1/iRonCub/meshes/stl/sim_sea_2-5_l_upper_thigh_prt.stl" scale="0.001 0.001 0.001"/>
      </geometry>
    </collision>
  </link>
  <joint name="l_leg_ft_sensor" type="fixed">
    <origin xyz="-0.0008301999999999962 7.519999999999749e-05 -0.07429999999999995" rpy="3.141592653589793 0 0"/>
    <parent link="l_hip_2"/>
    <child link="l_hip_3"/>
    <dynamics damping="0.1"/>
  </joint>
  <link name="l_upper_leg">
    <inertial>
      <origin xyz="0.0033868999999999913 0.00010179999999998524 -0.07891600000000001" rpy="1.5707963267948961 0 1.5707963267948961"/>
      <mass value="2.1684"/>
      <inertia ixx="0.007776127407181794" ixy="-0.00014893806511719572" ixz="-4.765101225034601e-06" iyy="0.001753647693486041" iyz="-0.00016405457894194634" izz="0.0077654145346884125"/>
    </inertial>
    <visual>
      <origin xyz="0.04370906139999997 -0.07010002459999994 0.24081299999999994" rpy="1.5707963267948961 0 1.5707963267948961"/>
      <geometry>
        <mesh filename="package://iRonCub-Mk1_v1/iRonCub/meshes/stl/sim_sea_2-5_l_thigh_prt.stl" scale="0.001 0.001 0.001"/>
      </geometry>
      <material name="green">
        <color rgba="0 1 0 1"/>
      </material>
    </visual>
    <collision>
      <origin xyz="0.04370906139999997 -0.07010002459999994 0.24081299999999994" rpy="1.5707963267948961 0 1.5707963267948961"/>
      <geometry>
        <mesh filename="package://iRonCub-Mk1_v1/iRonCub/meshes/stl/sim_sea_2-5_l_thigh_prt.stl" scale="0.001 0.001 0.001"/>
      </geometry>
    </collision>
  </link>
  <joint name="l_hip_yaw" type="revolute">
    <origin xyz="0 0 0.014399999999999996" rpy="-3.141592653589793 0 0"/>
    <axis xyz="0.0 2.220446049250313e-16 0.9999999999999998"/>
    <parent link="l_hip_3"/>
    <child link="l_upper_leg"/>
    <limit effort="37.0" lower="-1.3962634015954636" upper="1.3962634015954636" velocity="7.64"/>
    <dynamics damping="1.0" friction="0.0"/>
  </joint>
  <link name="l_upper_leg_back_contact"/>
  <joint name="l_upper_leg_back_contact_fixed_joint" type="fixed">
    <origin xyz="-0.051256699999999995 0 0.014599999999999946" rpy="0 1.5707963267948963 0"/>
    <parent link="l_upper_leg"/>
    <child link="l_upper_leg_back_contact"/>
    <dynamics damping="0.1"/>
  </joint>
  <link name="l_upper_leg_dh_frame"/>
  <joint name="l_upper_leg_dh_frame_fixed_joint" type="fixed">
    <origin xyz="0 0 -0.14582499999999995" rpy="1.5707963267948966 0 0"/>
    <parent link="l_upper_leg"/>
    <child link="l_upper_leg_dh_frame"/>
    <dynamics damping="0.1"/>
  </joint>
  <link name="l_lower_leg">
    <inertial>
      <origin xyz="0.0009997999999999951 0.0034968999999999695 -0.088567" rpy="1.5707963267948961 0 1.5707963267948961"/>
      <mass value="1.8324"/>
      <inertia ixx="0.005272923978185719" ixy="-0.00029820080035259695" ixz="8.41488031988615e-05" iyy="0.0018943923873043858" iyz="-0.00029014597407562784" izz="0.005687448808126723"/>
    </inertial>
    <visual>
      <origin xyz="0.04370906139999997 -0.07010002479999991 0.38663799999999987" rpy="1.5707963267948961 0 1.5707963267948961"/>
      <geometry>
        <mesh filename="package://iRonCub-Mk1_v1/iRonCub/meshes/stl/sim_sea_2-5_l_shank_prt.stl" scale="0.001 0.001 0.001"/>
      </geometry>
      <material name="black">
        <color rgba="0 0 0 1"/>
      </material>
    </visual>
    <collision>
      <origin xyz="0.04370906139999997 -0.07010002479999991 0.38663799999999987" rpy="1.5707963267948961 0 1.5707963267948961"/>
      <geometry>
        <mesh filename="package://iRonCub-Mk1_v1/iRonCub/meshes/stl/sim_sea_2-5_l_shank_prt.stl" scale="0.001 0.001 0.001"/>
      </geometry>
    </collision>
  </link>
  <joint name="l_knee" type="revolute">
    <origin xyz="0 0 -0.14582499999999995" rpy="0 0 0"/>
    <axis xyz="-2.220446049250313e-16 -0.9999999999999998 0.0"/>
    <parent link="l_upper_leg"/>
    <child link="l_lower_leg"/>
    <limit effort="37.0" lower="-2.1642082724729685" upper="0.06981317007977318" velocity="7.64"/>
    <dynamics damping="1.0" friction="0.0"/>
  </joint>
  <link name="l_ankle_1">
    <inertial>
      <origin xyz="0.015153099999999989 0.0009020000000000139 4.199999999998649e-05" rpy="1.5707963267948961 0 1.5707963267948961"/>
      <mass value="0.6798"/>
      <inertia ixx="0.00040447429734460005" ixy="-1.1322603878053663e-06" ixz="3.046651057758992e-05" iyy="0.0004478873540695352" iyz="2.5726583414130826e-06" izz="0.0003076030453774591"/>
    </inertial>
    <visual>
      <origin xyz="0.04370906139999997 -0.07010002479999985 0.5871379999999998" rpy="1.5707963267948961 0 1.5707963267948961"/>
      <geometry>
        <mesh filename="package://iRonCub-Mk1_v1/iRonCub/meshes/stl/sim_sea_2-5_l_ankle_prt.stl" scale="0.001 0.001 0.001"/>
      </geometry>
      <material name="red">
        <color rgba="1 0 0 1"/>
      </material>
    </visual>
    <collision>
      <origin xyz="0.04370906139999997 -0.07010002479999985 0.5871379999999998" rpy="1.5707963267948961 0 1.5707963267948961"/>
      <geometry>
        <mesh filename="package://iRonCub-Mk1_v1/iRonCub/meshes/stl/sim_sea_2-5_l_ankle_prt.stl" scale="0.001 0.001 0.001"/>
      </geometry>
    </collision>
  </link>
  <joint name="l_ankle_pitch" type="revolute">
    <origin xyz="0 0 -0.20049999999999996" rpy="0 0 0"/>
    <axis xyz="2.220446049250313e-16 0.9999999999999998 0.0"/>
    <parent link="l_lower_leg"/>
    <child link="l_ankle_1"/>
    <limit effort="37.0" lower="-0.6108652381980153" upper="0.6108652381980153" velocity="7.64"/>
    <dynamics damping="1.0" friction="0.0"/>
  </joint>
  <link name="l_ankle_2">
    <inertial>
      <origin xyz="0.0011446999999999985 3.599999999992498e-06 -0.03852" rpy="1.5707963267948961 0 1.5707963267948961"/>
      <mass value="0.265122"/>
      <inertia ixx="0.01" ixy="-4.74606e-08" ixz="4.94571e-08" iyy="0.01" iyz="-4.29975e-06" izz="0.01"/>
    </inertial>
    <visual>
      <origin xyz="0.04368169961858297 -0.07017520019076885 0.5871379999999998" rpy="1.5707963267948961 0 1.5707963267948961"/>
      <geometry>
        <mesh filename="package://iRonCub-Mk1_v1/iRonCub/meshes/stl/sim_sea_2-5_l_foot_prt.stl" scale="0.001 0.001 0.001"/>
      </geometry>
      <material name="blue">
        <color rgba="0 0 1 1"/>
      </material>
    </visual>
    <collision>
      <origin xyz="0.04368169961858297 -0.07017520019076885 0.5871379999999998" rpy="1.5707963267948961 0 1.5707963267948961"/>
      <geometry>
        <mesh filename="package://iRonCub-Mk1_v1/iRonCub/meshes/stl/sim_sea_2-5_l_foot_prt.stl" scale="0.001 0.001 0.001"/>
      </geometry>
    </collision>
  </link>
  <joint name="l_ankle_roll" type="revolute">
    <origin xyz="0 0 0" rpy="0 0 0"/>
    <axis xyz="0.9999999999999998 0.0 2.220446049250313e-16"/>
    <parent link="l_ankle_1"/>
    <child link="l_ankle_2"/>
    <limit effort="37.0" lower="-0.4363323129985824" upper="0.4363323129985824" velocity="7.64"/>
    <dynamics damping="1.0" friction="0.0"/>
  </joint>
  <link name="l_foot">
    <inertial>
      <origin xyz="0.03366689999999999 -0.005373499999999989 -0.0011639999999999429" rpy="-1.5707963267948961 0 -1.5707963267948961"/>
      <mass value="0.382968"/>
      <inertia ixx="0.00121242" ixy="-3.69533e-07" ixz="5.79273e-05" iyy="0.00141712" iyz="-7.64972e-06" izz="0.000273846"/>
    </inertial>
    <visual>
      <origin xyz="0.04720906119999997 0.07010002480000013 -0.6474380002860819" rpy="-1.5707963267948961 0 -1.5707963267948961"/>
      <geometry>
        <mesh filename="package://iRonCub-Mk1_v1/iRonCub/meshes/stl/sim_sea_2-5_l_sole_prt.stl" scale="0.001 0.001 0.001"/>
      </geometry>
      <material name="yellow">
        <color rgba="1 1 0 1"/>
      </material>
    </visual>
    <collision>
      <origin xyz="0.03 -0.005 0.014" rpy="0.0 0.0 0.0"/>
      <geometry>
        <box size="0.16 0.072 0.001"/>
      </geometry>
    </collision>
  </link>
  <joint name="l_foot_ft_sensor" type="fixed">
    <origin xyz="-0.003500000000000003 0 -0.0605" rpy="3.141592653589793 0 0"/>
    <parent link="l_ankle_2"/>
    <child link="l_foot"/>
    <dynamics damping="0.1"/>
  </joint>
  <link name="l_sole"/>
  <joint name="l_sole_fixed_joint" type="fixed">
    <origin xyz="0.003500000000000003 0 0.0040000000000000036" rpy="-3.141592653589793 0 0"/>
    <parent link="l_foot"/>
    <child link="l_sole"/>
    <dynamics damping="0.1"/>
  </joint>
  <link name="r_hip_1">
    <inertial>
      <origin xyz="-0.0005145000000000149 -0.038075299999999986 -7.099999999998774e-05" rpy="1.5707963267948961 0 1.5707963267948961"/>
      <mass value="0.919978"/>
      <inertia ixx="0.000404268" ixy="-1.26852e-06" ixz="1.11055e-06" iyy="0.000574741" iyz="-7.69474e-07" izz="0.000580025"/>
    </inertial>
    <visual>
      <origin xyz="0.04285150000011213 0.025999999999999232 0.1519129999999679" rpy="1.5707963267948961 0 1.5707963267948961"/>
      <geometry>
        <mesh filename="package://iRonCub-Mk1_v1/iRonCub/meshes/stl/sim_sea_2-5_r_hip_1_prt.stl" scale="0.001 0.001 0.001"/>
      </geometry>
      <material name="pink">
        <color rgba="1 0 1 1"/>
      </material>
    </visual>
    <collision>
      <origin xyz="0.04285150000011213 0.025999999999999232 0.1519129999999679" rpy="1.5707963267948961 0 1.5707963267948961"/>
      <geometry>
        <mesh filename="package://iRonCub-Mk1_v1/iRonCub/meshes/stl/sim_sea_2-5_r_hip_1_prt.stl" scale="0.001 0.001 0.001"/>
      </geometry>
    </collision>
  </link>
  <joint name="r_hip_pitch" type="revolute">
    <origin xyz="0.006451499999999992 0.025999999999999968 -0.11991299999999999" rpy="0 0 -3.141592653589793"/>
    <axis xyz="-2.220446049250313e-16 -0.9999999999999998 0.0"/>
    <parent link="root_link"/>
    <child link="r_hip_1"/>
    <limit effort="55.5" lower="-0.7853981633974483" upper="2.3387411976724017" velocity="5.1"/>
    <dynamics damping="1.0" friction="0.0"/>
  </joint>
  <link name="r_hip_2">
    <inertial>
      <origin xyz="-0.0009315000000000018 8.09999999998312e-06 -0.04480899999999996" rpy="1.5707963267948961 0 1.5707963267948961"/>
      <mass value="0.413242"/>
      <inertia ixx="0.00046914" ixy="-4.76597e-08" ixz="7.12496e-08" iyy="0.000277108" iyz="3.3401e-06" izz="0.000303891"/>
    </inertial>
    <visual>
      <origin xyz="0.04285149980937101 0.07010000000000424 0.15191299999996632" rpy="1.5707963267948961 0 1.5707963267948961"/>
      <geometry>
        <mesh filename="package://iRonCub-Mk1_v1/iRonCub/meshes/stl/sim_sea_2-5_r_hip_2_prt.stl" scale="0.001 0.001 0.001"/>
      </geometry>
      <material name="cyan">
        <color rgba="0 1 1 1"/>
      </material>
    </visual>
    <collision>
      <origin xyz="0.04285149980937101 0.07010000000000424 0.15191299999996632" rpy="1.5707963267948961 0 1.5707963267948961"/>
      <geometry>
        <mesh filename="package://iRonCub-Mk1_v1/iRonCub/meshes/stl/sim_sea_2-5_r_hip_2_prt.stl" scale="0.001 0.001 0.001"/>
      </geometry>
    </collision>
  </link>
  <joint name="r_hip_roll" type="revolute">
    <origin xyz="0 -0.04409999999999998 0" rpy="0 0 0"/>
    <axis xyz="-0.9999999999999998 0.0 -2.220446049250313e-16"/>
    <parent link="r_hip_1"/>
    <child link="r_hip_2"/>
    <limit effort="37.0" lower="-0.3490658503988659" upper="2.0943951023931953" velocity="7.64"/>
    <dynamics damping="1.0" friction="0.0"/>
  </joint>
  <link name="r_hip_3">
    <inertial>
      <origin xyz="-0.00012300000000000505 -0.0002822999999999992 0.008718000000000031" rpy="-1.5707963267948961 0 -1.5707963267948961"/>
      <mass value="0.126212"/>
      <inertia ixx="0.01" ixy="2.67901e-07" ixz="-4.41463e-09" iyy="0.01" iyz="3.32338e-08" izz="0.01"/>
    </inertial>
    <visual>
      <origin xyz="0.0437090152 -0.07009999189999992 -0.22621299999996644" rpy="-1.5707963267948961 0 -1.5707963267948961"/>
      <geometry>
        <mesh filename="package://iRonCub-Mk1_v1/iRonCub/meshes/stl/sim_sea_2-5_r_upper_thigh_prt.stl" scale="0.001 0.001 0.001"/>
      </geometry>
      <material name="green">
        <color rgba="0 1 0 1"/>
      </material>
    </visual>
    <collision>
      <origin xyz="0.0437090152 -0.07009999189999992 -0.22621299999996644" rpy="-1.5707963267948961 0 -1.5707963267948961"/>
      <geometry>
        <mesh filename="package://iRonCub-Mk1_v1/iRonCub/meshes/stl/sim_sea_2-5_r_upper_thigh_prt.stl" scale="0.001 0.001 0.001"/>
      </geometry>
    </collision>
  </link>
  <joint name="r_leg_ft_sensor" type="fixed">
    <origin xyz="-0.0009362999999999941 1.3899999999969492e-05 -0.07429999999999995" rpy="3.141592653589793 0 0"/>
    <parent link="r_hip_2"/>
    <child link="r_hip_3"/>
    <dynamics damping="0.1"/>
  </joint>
  <link name="r_upper_leg">
    <inertial>
      <origin xyz="0.0033999999999999933 -2.9100000000018e-05 -0.078954" rpy="1.5707963267948961 0 1.5707963267948961"/>
      <mass value="2.1635"/>
      <inertia ixx="0.0077705029312875665" ixy="0.00015544502130009113" ixz="6.5763333655041776e-06" iyy="0.001750687934586949" iyz="-0.00016388268004075972" izz="0.0077581397411668595"/>
    </inertial>
    <visual>
      <origin xyz="0.0437090152 0.07009999190000003 0.24081299999999994" rpy="1.5707963267948961 0 1.5707963267948961"/>
      <geometry>
        <mesh filename="package://iRonCub-Mk1_v1/iRonCub/meshes/stl/sim_sea_2-5_r_thigh_prt.stl" scale="0.001 0.001 0.001"/>
      </geometry>
      <material name="white">
        <color rgba="1 1 1 1"/>
      </material>
    </visual>
    <collision>
      <origin xyz="0.0437090152 0.07009999190000003 0.24081299999999994" rpy="1.5707963267948961 0 1.5707963267948961"/>
      <geometry>
        <mesh filename="package://iRonCub-Mk1_v1/iRonCub/meshes/stl/sim_sea_2-5_r_thigh_prt.stl" scale="0.001 0.001 0.001"/>
      </geometry>
    </collision>
  </link>
  <joint name="r_hip_yaw" type="revolute">
    <origin xyz="0 0 0.014399999999999996" rpy="-3.141592653589793 0 0"/>
    <axis xyz="0.0 -2.220446049250313e-16 -0.9999999999999998"/>
    <parent link="r_hip_3"/>
    <child link="r_upper_leg"/>
    <limit effort="37.0" lower="-1.3962634015954636" upper="1.3962634015954636" velocity="7.64"/>
    <dynamics damping="1.0" friction="0.0"/>
  </joint>
  <link name="r_upper_leg_back_contact"/>
  <joint name="r_upper_leg_back_contact_fixed_joint" type="fixed">
    <origin xyz="-0.051199800000000004 0 0.014599999999999946" rpy="0 1.5707963267948963 0"/>
    <parent link="r_upper_leg"/>
    <child link="r_upper_leg_back_contact"/>
    <dynamics damping="0.1"/>
  </joint>
  <link name="r_upper_leg_dh_frame"/>
  <joint name="r_upper_leg_dh_frame_fixed_joint" type="fixed">
    <origin xyz="0 0 -0.14582499999999995" rpy="1.5707963267948966 0 0"/>
    <parent link="r_upper_leg"/>
    <child link="r_upper_leg_dh_frame"/>
    <dynamics damping="0.1"/>
  </joint>
  <link name="r_lower_leg">
    <inertial>
      <origin xyz="0.0012363999999999917 -0.003513100000000033 -0.08879400000000004" rpy="1.5707963267948961 0 1.5707963267948961"/>
      <mass value="1.832"/>
      <inertia ixx="0.005276871486541036" ixy="0.0002847746287365357" ixz="-6.915382566020098e-05" iyy="0.001892922008115745" iyz="-0.0003287307187320742" izz="0.005692125857783254"/>
    </inertial>
    <visual>
      <origin xyz="0.0437090152 0.07009999200000007 0.38663799999999987" rpy="1.5707963267948961 0 1.5707963267948961"/>
      <geometry>
        <mesh filename="package://iRonCub-Mk1_v1/iRonCub/meshes/stl/sim_sea_2-5_r_shank_prt.stl" scale="0.001 0.001 0.001"/>
      </geometry>
      <material name="dblue">
        <color rgba="0 0 0.8 1"/>
      </material>
    </visual>
    <collision>
      <origin xyz="0.0437090152 0.07009999200000007 0.38663799999999987" rpy="1.5707963267948961 0 1.5707963267948961"/>
      <geometry>
        <mesh filename="package://iRonCub-Mk1_v1/iRonCub/meshes/stl/sim_sea_2-5_r_shank_prt.stl" scale="0.001 0.001 0.001"/>
      </geometry>
    </collision>
  </link>
  <joint name="r_knee" type="revolute">
    <origin xyz="0 0 -0.14582499999999995" rpy="0 0 0"/>
    <axis xyz="-2.220446049250313e-16 -0.9999999999999998 0.0"/>
    <parent link="r_upper_leg"/>
    <child link="r_lower_leg"/>
    <limit effort="37.0" lower="-2.1642082724729685" upper="0.06981317007977318" velocity="7.64"/>
    <dynamics damping="1.0" friction="0.0"/>
  </joint>
  <link name="r_lower_leg_skin_0"/>
  <joint name="r_lower_leg_skin_0_fixed_joint" type="fixed">
    <origin xyz="0.05441169999999998 -0.03121489999999999 -0.002634000000000025" rpy="2.0917380908554746e-06 -1.4153067624694633 2.48648458622082"/>
    <parent link="r_lower_leg"/>
    <child link="r_lower_leg_skin_0"/>
    <dynamics damping="0.1"/>
  </joint>
  <link name="r_lower_leg_skin_3"/>
  <joint name="r_lower_leg_skin_3_fixed_joint" type="fixed">
    <origin xyz="0.05157878999999999 0.030420499999999996 -0.0028429999999999844" rpy="0 -1.4295105408285231 -2.3039148418553874"/>
    <parent link="r_lower_leg"/>
    <child link="r_lower_leg_skin_3"/>
    <dynamics damping="0.1"/>
  </joint>
  <link name="r_lower_leg_skin_4"/>
  <joint name="r_lower_leg_skin_4_fixed_joint" type="fixed">
    <origin xyz="0.05831029999999999 0.016783599999999996 0.007272000000000001" rpy="-2.9863636151870843e-07 -1.256367488755018 -2.758923800870981"/>
    <parent link="r_lower_leg"/>
    <child link="r_lower_leg_skin_4"/>
    <dynamics damping="0.1"/>
  </joint>
  <link name="r_lower_leg_skin_5"/>
  <joint name="r_lower_leg_skin_5_fixed_joint" type="fixed">
    <origin xyz="0.06365039999999998 0.00030939999999998746 -0.0019720000000000293" rpy="0 -1.3865221506831833 -3.1414716980716264"/>
    <parent link="r_lower_leg"/>
    <child link="r_lower_leg_skin_5"/>
    <dynamics damping="0.1"/>
  </joint>
  <link name="r_lower_leg_skin_6"/>
  <joint name="r_lower_leg_skin_6_fixed_joint" type="fixed">
    <origin xyz="0.05208553999999999 0.03044339999999999 -0.022148999999999974" rpy="-3.1415892795257605 -1.4678512341064953 0.8374928890768593"/>
    <parent link="r_lower_leg"/>
    <child link="r_lower_leg_skin_6"/>
    <dynamics damping="0.1"/>
  </joint>
  <link name="r_lower_leg_skin_9"/>
  <joint name="r_lower_leg_skin_9_fixed_joint" type="fixed">
    <origin xyz="0.05982139999999998 0.01679719999999999 -0.03096199999999999" rpy="-3.1415920235620423 -1.3422475532506952 0.37929447771782354"/>
    <parent link="r_lower_leg"/>
    <child link="r_lower_leg_skin_9"/>
    <dynamics damping="0.1"/>
  </joint>
  <link name="r_lower_leg_skin_10"/>
  <joint name="r_lower_leg_skin_10_fixed_joint" type="fixed">
    <origin xyz="0.06446069999999998 0.00034239999999997883 -0.021204999999999974" rpy="3.141592653553929 -1.4709580354104241 0.00043002167526072775"/>
    <parent link="r_lower_leg"/>
    <child link="r_lower_leg_skin_10"/>
    <dynamics damping="0.1"/>
  </joint>
  <link name="r_lower_leg_skin_11"/>
  <joint name="r_lower_leg_skin_11_fixed_joint" type="fixed">
    <origin xyz="0.060710799999999975 -0.016091600000000025 -0.030884999999999996" rpy="-3.1415921825227295 -1.32811804060386 -0.27213836787954737"/>
    <parent link="r_lower_leg"/>
    <child link="r_lower_leg_skin_11"/>
    <dynamics damping="0.1"/>
  </joint>
  <link name="r_lower_leg_skin_14"/>
  <joint name="r_lower_leg_skin_14_fixed_joint" type="fixed">
    <origin xyz="0.05504769999999998 -0.031175900000000006 -0.02190000000000003" rpy="-3.141591818848249 -1.4650273563521197 -0.6540334071673023"/>
    <parent link="r_lower_leg"/>
    <child link="r_lower_leg_skin_14"/>
    <dynamics damping="0.1"/>
  </joint>
  <link name="r_lower_leg_skin_15"/>
  <joint name="r_lower_leg_skin_15_fixed_joint" type="fixed">
    <origin xyz="0.05917079999999998 -0.016178800000000007 0.0072429999999999994" rpy="4.274842569949443e-07 -1.2520363307607896 2.8679885947088186"/>
    <parent link="r_lower_leg"/>
    <child link="r_lower_leg_skin_15"/>
    <dynamics damping="0.1"/>
  </joint>
  <link name="r_lower_leg_skin_16"/>
  <joint name="r_lower_leg_skin_16_fixed_joint" type="fixed">
    <origin xyz="0.027287599999999978 -0.050286899999999995 -0.004549000000000025" rpy="1.3307591512293707e-05 -1.5326085351498482 1.9628024283508803"/>
    <parent link="r_lower_leg"/>
    <child link="r_lower_leg_skin_16"/>
    <dynamics damping="0.1"/>
  </joint>
  <link name="r_lower_leg_skin_17"/>
  <joint name="r_lower_leg_skin_17_fixed_joint" type="fixed">
    <origin xyz="0.027874999999999976 -0.05031190000000001 -0.023882000000000014" rpy="-3.141564526201752 -1.563662402374811 -1.1802250875588731"/>
    <parent link="r_lower_leg"/>
    <child link="r_lower_leg_skin_17"/>
    <dynamics damping="0.1"/>
  </joint>
  <link name="r_lower_leg_skin_19"/>
  <joint name="r_lower_leg_skin_19_fixed_joint" type="fixed">
    <origin xyz="0.03575341 0.041062799999999997 0.006064999999999987" rpy="-8.908777174257102e-07 -1.4349869697782824 -2.1586361801672447"/>
    <parent link="r_lower_leg"/>
    <child link="r_lower_leg_skin_19"/>
    <dynamics damping="0.1"/>
  </joint>
  <link name="r_lower_leg_skin_20"/>
  <joint name="r_lower_leg_skin_20_fixed_joint" type="fixed">
    <origin xyz="0.0234419 0.047990799999999986 -0.004952000000000012" rpy="-3.2055654966350685e-06 -1.5001551303072314 -1.8675509241250097"/>
    <parent link="r_lower_leg"/>
    <child link="r_lower_leg_skin_20"/>
    <dynamics damping="0.1"/>
  </joint>
  <link name="r_lower_leg_skin_21"/>
  <joint name="r_lower_leg_skin_21_fixed_joint" type="fixed">
    <origin xyz="0.024270400000000004 0.04853779999999998 -0.024276999999999993" rpy="2.2967114955750172e-05 -1.5554551388057172 -1.8741197231626954"/>
    <parent link="r_lower_leg"/>
    <child link="r_lower_leg_skin_21"/>
    <dynamics damping="0.1"/>
  </joint>
  <link name="r_lower_leg_skin_28"/>
  <joint name="r_lower_leg_skin_28_fixed_joint" type="fixed">
    <origin xyz="0.04087215999999998 -0.0424399 -0.03275600000000001" rpy="3.1415808886539165 -1.5225246216918655 -0.9296810297631274"/>
    <parent link="r_lower_leg"/>
    <child link="r_lower_leg_skin_28"/>
    <dynamics damping="0.1"/>
  </joint>
  <link name="r_lower_leg_skin_29"/>
  <joint name="r_lower_leg_skin_29_fixed_joint" type="fixed">
    <origin xyz="0.03846637999999998 -0.04351590000000001 -0.05242000000000002" rpy="3.1415801704422774 -1.5342984156258153 -0.9154363466305139"/>
    <parent link="r_lower_leg"/>
    <child link="r_lower_leg_skin_29"/>
    <dynamics damping="0.1"/>
  </joint>
  <link name="r_lower_leg_skin_31"/>
  <joint name="r_lower_leg_skin_31_fixed_joint" type="fixed">
    <origin xyz="0.03914639999999998 -0.042270899999999986 0.006327000000000027" rpy="-6.583817471389409e-07 -1.4186494462021593 2.2085303298592955"/>
    <parent link="r_lower_leg"/>
    <child link="r_lower_leg_skin_31"/>
    <dynamics damping="0.1"/>
  </joint>
  <link name="r_lower_leg_skin_32"/>
  <joint name="r_lower_leg_skin_32_fixed_joint" type="fixed">
    <origin xyz="0.045983029999999994 0.03258469999999997 -0.080733" rpy="-3.141590149878832 -1.5223828979770995 0.6459403808870791"/>
    <parent link="r_lower_leg"/>
    <child link="r_lower_leg_skin_32"/>
    <dynamics damping="0.1"/>
  </joint>
  <link name="r_lower_leg_skin_35"/>
  <joint name="r_lower_leg_skin_35_fixed_joint" type="fixed">
    <origin xyz="0.04774867999999998 -0.031231900000000007 -0.08011299999999999" rpy="-3.1415866827530436 -1.517584673322529 -0.541532486468427"/>
    <parent link="r_lower_leg"/>
    <child link="r_lower_leg_skin_35"/>
    <dynamics damping="0.1"/>
  </joint>
  <link name="r_lower_leg_skin_36"/>
  <joint name="r_lower_leg_skin_36_fixed_joint" type="fixed">
    <origin xyz="0.05322409999999998 -0.015601800000000027 -0.088362" rpy="-3.141590341443774 -1.5158726528065043 -0.20740733566009956"/>
    <parent link="r_lower_leg"/>
    <child link="r_lower_leg_skin_36"/>
    <dynamics damping="0.1"/>
  </joint>
  <link name="r_lower_leg_skin_37"/>
  <joint name="r_lower_leg_skin_37_fixed_joint" type="fixed">
    <origin xyz="0.055257199999999985 0.0009643999999999764 -0.078318" rpy="-3.1415818045233417 -1.5231833689799856 0.007524505830633038"/>
    <parent link="r_lower_leg"/>
    <child link="r_lower_leg_skin_37"/>
    <dynamics damping="0.1"/>
  </joint>
  <link name="r_lower_leg_skin_38"/>
  <joint name="r_lower_leg_skin_38_fixed_joint" type="fixed">
    <origin xyz="0.04880468999999998 -0.03126290000000001 -0.060757000000000005" rpy="3.1415866519890936 -1.515729955403707 -0.5421535995897704"/>
    <parent link="r_lower_leg"/>
    <child link="r_lower_leg_skin_38"/>
    <dynamics damping="0.1"/>
  </joint>
  <link name="r_lower_leg_skin_41"/>
  <joint name="r_lower_leg_skin_41_fixed_joint" type="fixed">
    <origin xyz="0.05660089999999998 -0.015912900000000008 -0.049853999999999954" rpy="-3.1415919882511 -1.4068134359704096 -0.24823308941290081"/>
    <parent link="r_lower_leg"/>
    <child link="r_lower_leg_skin_41"/>
    <dynamics damping="0.1"/>
  </joint>
  <link name="r_lower_leg_skin_42"/>
  <joint name="r_lower_leg_skin_42_fixed_joint" type="fixed">
    <origin xyz="0.05701059999999998 0.000796199999999983 -0.059079999999999966" rpy="3.14158970239263 -1.4352475041611767 0.006879436515041273"/>
    <parent link="r_lower_leg"/>
    <child link="r_lower_leg_skin_42"/>
    <dynamics damping="0.1"/>
  </joint>
  <link name="r_lower_leg_skin_43"/>
  <joint name="r_lower_leg_skin_43_fixed_joint" type="fixed">
    <origin xyz="0.04712543999999999 0.03236529999999998 -0.06136200000000003" rpy="-3.1415913662061943 -1.5384303823718677 0.6242175236666732"/>
    <parent link="r_lower_leg"/>
    <child link="r_lower_leg_skin_43"/>
    <dynamics damping="0.1"/>
  </joint>
  <link name="r_lower_leg_skin_46"/>
  <joint name="r_lower_leg_skin_46_fixed_joint" type="fixed">
    <origin xyz="0.05581569999999999 0.01721639999999998 -0.05018" rpy="-3.141589878093782 -1.4275988160283246 0.3256077108756132"/>
    <parent link="r_lower_leg"/>
    <child link="r_lower_leg_skin_46"/>
    <dynamics damping="0.1"/>
  </joint>
  <link name="r_lower_leg_skin_47"/>
  <joint name="r_lower_leg_skin_47_fixed_joint" type="fixed">
    <origin xyz="0.052641649999999984 0.017638799999999975 -0.08886" rpy="3.141589635185022 -1.51690559405793 0.26264042505775587"/>
    <parent link="r_lower_leg"/>
    <child link="r_lower_leg_skin_47"/>
    <dynamics damping="0.1"/>
  </joint>
  <link name="r_lower_leg_skin_49"/>
  <joint name="r_lower_leg_skin_49_fixed_joint" type="fixed">
    <origin xyz="0.04113139 0.03243849999999996 -0.138859" rpy="-3.141589347506919 -1.489961356950246 0.729763592113092"/>
    <parent link="r_lower_leg"/>
    <child link="r_lower_leg_skin_49"/>
    <dynamics damping="0.1"/>
  </joint>
  <link name="r_lower_leg_skin_50"/>
  <joint name="r_lower_leg_skin_50_fixed_joint" type="fixed">
    <origin xyz="0.04301696299999999 0.03252729999999997 -0.11946899999999999" rpy="3.1415906959631426 -1.4990073263616448 0.6957840200808761"/>
    <parent link="r_lower_leg"/>
    <child link="r_lower_leg_skin_50"/>
    <dynamics damping="0.1"/>
  </joint>
  <link name="r_lower_leg_skin_51"/>
  <joint name="r_lower_leg_skin_51_fixed_joint" type="fixed">
    <origin xyz="0.05141583999999999 0.01775899999999997 -0.10820600000000002" rpy="-3.141588901786459 -1.5062847571686897 0.27207993571349487"/>
    <parent link="r_lower_leg"/>
    <child link="r_lower_leg_skin_51"/>
    <dynamics damping="0.1"/>
  </joint>
  <link name="r_lower_leg_skin_52"/>
  <joint name="r_lower_leg_skin_52_fixed_joint" type="fixed">
    <origin xyz="0.052998339999999984 0.001266399999999973 -0.11689500000000003" rpy="-3.1415916404202857 -1.5031867442105085 0.010871726099418466"/>
    <parent link="r_lower_leg"/>
    <child link="r_lower_leg_skin_52"/>
    <dynamics damping="0.1"/>
  </joint>
  <link name="r_lower_leg_skin_53"/>
  <joint name="r_lower_leg_skin_53_fixed_joint" type="fixed">
    <origin xyz="0.05207313999999998 -0.015433900000000028 -0.10765399999999997" rpy="3.1415906398667093 -1.5059530744712215 -0.21140732289166783"/>
    <parent link="r_lower_leg"/>
    <child link="r_lower_leg_skin_53"/>
    <dynamics damping="0.1"/>
  </joint>
  <link name="r_lower_leg_skin_54"/>
  <joint name="r_lower_leg_skin_54_fixed_joint" type="fixed">
    <origin xyz="0.045127099999999976 -0.03074890000000001 -0.11878700000000003" rpy="3.141588251928216 -1.4974514557145624 -0.5751153744726872"/>
    <parent link="r_lower_leg"/>
    <child link="r_lower_leg_skin_54"/>
    <dynamics damping="0.1"/>
  </joint>
  <link name="r_lower_leg_skin_55"/>
  <joint name="r_lower_leg_skin_55_fixed_joint" type="fixed">
    <origin xyz="0.04350267899999998 -0.030488900000000027 -0.13814300000000007" rpy="3.1415890648626297 -1.4899578703820784 -0.5972199437885269"/>
    <parent link="r_lower_leg"/>
    <child link="r_lower_leg_skin_55"/>
    <dynamics damping="0.1"/>
  </joint>
  <link name="r_lower_leg_skin_56"/>
  <joint name="r_lower_leg_skin_56_fixed_joint" type="fixed">
    <origin xyz="0.049268409999999985 -0.015121000000000037 -0.1462179999999999" rpy="-3.141589204039199 -1.491248198275157 -0.22348447640041147"/>
    <parent link="r_lower_leg"/>
    <child link="r_lower_leg_skin_56"/>
    <dynamics damping="0.1"/>
  </joint>
  <link name="r_lower_leg_skin_60"/>
  <joint name="r_lower_leg_skin_60_fixed_joint" type="fixed">
    <origin xyz="0.04836967999999999 0.018055999999999968 -0.14693799999999996" rpy="-3.141591733372508 -1.4898596852742692 0.3029518719544257"/>
    <parent link="r_lower_leg"/>
    <child link="r_lower_leg_skin_60"/>
    <dynamics damping="0.1"/>
  </joint>
  <link name="r_lower_leg_skin_61"/>
  <joint name="r_lower_leg_skin_61_fixed_joint" type="fixed">
    <origin xyz="0.051619539999999985 0.0014265999999999723 -0.13616899999999993" rpy="-3.141591009251115 -1.4960209708613401 0.013201427520491136"/>
    <parent link="r_lower_leg"/>
    <child link="r_lower_leg_skin_61"/>
    <dynamics damping="0.1"/>
  </joint>
  <link name="r_ankle_1">
    <inertial>
      <origin xyz="0.01514359999999999 -0.000868600000000011 4.199999999998649e-05" rpy="1.5707963267948961 0 1.5707963267948961"/>
      <mass value="0.6803"/>
      <inertia ixx="0.0004046188489317631" ixy="7.498192869450776e-07" ixz="-3.013494676905822e-05" iyy="0.00044863365466369986" iyz="2.5726697409005395e-06" izz="0.00030823593913944066"/>
    </inertial>
    <visual>
      <origin xyz="0.0437090152 0.07009999200000011 0.5871379999999998" rpy="1.5707963267948961 0 1.5707963267948961"/>
      <geometry>
        <mesh filename="package://iRonCub-Mk1_v1/iRonCub/meshes/stl/sim_sea_2-5_r_ankle_prt.stl" scale="0.001 0.001 0.001"/>
      </geometry>
      <material name="dgreen">
        <color rgba="0.1 0.8 0.1 1"/>
      </material>
    </visual>
    <collision>
      <origin xyz="0.0437090152 0.07009999200000011 0.5871379999999998" rpy="1.5707963267948961 0 1.5707963267948961"/>
      <geometry>
        <mesh filename="package://iRonCub-Mk1_v1/iRonCub/meshes/stl/sim_sea_2-5_r_ankle_prt.stl" scale="0.001 0.001 0.001"/>
      </geometry>
    </collision>
  </link>
  <joint name="r_ankle_pitch" type="revolute">
    <origin xyz="0 0 -0.20049999999999996" rpy="0 0 0"/>
    <axis xyz="2.220446049250313e-16 0.9999999999999998 0.0"/>
    <parent link="r_lower_leg"/>
    <child link="r_ankle_1"/>
    <limit effort="37.0" lower="-0.6108652381980153" upper="0.6108652381980153" velocity="7.64"/>
    <dynamics damping="1.0" friction="0.0"/>
  </joint>
  <link name="r_ankle_2">
    <inertial>
      <origin xyz="0.0011445999999999956 3.599999999992498e-06 -0.03852" rpy="1.5707963267948961 0 1.5707963267948961"/>
      <mass value="0.265122"/>
      <inertia ixx="0.01" ixy="-4.74606e-08" ixz="4.94571e-08" iyy="0.01" iyz="-4.29975e-06" izz="0.01"/>
    </inertial>
    <visual>
      <origin xyz="0.043787799618642 0.07008610019070811 0.5871379999999998" rpy="1.5707963267948961 0 1.5707963267948961"/>
      <geometry>
        <mesh filename="package://iRonCub-Mk1_v1/iRonCub/meshes/stl/sim_sea_2-5_r_foot_prt.stl" scale="0.001 0.001 0.001"/>
      </geometry>
      <material name="gray">
        <color rgba="0.5 0.5 0.5 1"/>
      </material>
    </visual>
    <collision>
      <origin xyz="0.043787799618642 0.07008610019070811 0.5871379999999998" rpy="1.5707963267948961 0 1.5707963267948961"/>
      <geometry>
        <mesh filename="package://iRonCub-Mk1_v1/iRonCub/meshes/stl/sim_sea_2-5_r_foot_prt.stl" scale="0.001 0.001 0.001"/>
      </geometry>
    </collision>
  </link>
  <joint name="r_ankle_roll" type="revolute">
    <origin xyz="0 0 0" rpy="0 0 0"/>
    <axis xyz="-0.9999999999999998 0.0 -2.220446049250313e-16"/>
    <parent link="r_ankle_1"/>
    <child link="r_ankle_2"/>
    <limit effort="37.0" lower="-0.4363323129985824" upper="0.4363323129985824" velocity="7.64"/>
    <dynamics damping="1.0" friction="0.0"/>
  </joint>
  <link name="r_foot">
    <inertial>
      <origin xyz="0.033600099999999994 0.005371899999999999 -0.001146999999999898" rpy="-1.5707963267948961 0 -1.5707963267948961"/>
      <mass value="0.382866"/>
      <inertia ixx="0.00120946" ixy="3.74585e-07" ixz="-5.78759e-05" iyy="0.00141439" iyz="-7.80325e-06" izz="0.000273599"/>
    </inertial>
    <visual>
      <origin xyz="0.04720901500000001 -0.07009999199999985 -0.6474380002860779" rpy="-1.5707963267948961 0 -1.5707963267948961"/>
      <geometry>
        <mesh filename="package://iRonCub-Mk1_v1/iRonCub/meshes/stl/sim_sea_2-5_r_sole_prt.stl" scale="0.001 0.001 0.001"/>
      </geometry>
      <material name="green">
        <color rgba="0 1 0 1"/>
      </material>
    </visual>
    <collision>
      <origin xyz="0.03 0.005 0.014" rpy="0.0 0.0 0.0"/>
      <geometry>
        <box size="0.16 0.072 0.001"/>
      </geometry>
    </collision>
  </link>
  <joint name="r_foot_ft_sensor" type="fixed">
    <origin xyz="-0.003500000000000003 0 -0.0605" rpy="3.141592653589793 0 0"/>
    <parent link="r_ankle_2"/>
    <child link="r_foot"/>
    <dynamics damping="0.1"/>
  </joint>
  <link name="r_sole"/>
  <joint name="r_sole_fixed_joint" type="fixed">
    <origin xyz="0.003500000000000003 0 0.0040000000000000036" rpy="-3.141592653589793 0 0"/>
    <parent link="r_foot"/>
    <child link="r_sole"/>
    <dynamics damping="0.1"/>
  </joint>
  <link name="base_link"/>
  <joint name="base_fixed_joint" type="fixed">
  <origin xyz="0 0 0" rpy="0 -0 0"/>
  <axis xyz="0 0 0"/>
  <parent link="base_link"/>
  <child link="root_link"/>
</joint>
  <link name="l_foot_dh_frame"/>
  <joint name="l_foot_dh_frame_fixed_joint" type="fixed">
  <origin xyz="0.0 0 0.004" rpy="0 1.5708 0"/>
  <axis xyz="0 0 0"/>
  <parent link="l_foot"/>
  <child link="l_foot_dh_frame"/>
</joint>
  <link name="r_foot_dh_frame"/>
  <joint name="r_foot_dh_frame_fixed_joint" type="fixed">
  <origin xyz="0.0 0 0.004" rpy="0 1.5708 0"/>
  <axis xyz="0 0 0"/>
  <parent link="r_foot"/>
  <child link="r_foot_dh_frame"/>
</joint>
  <link name="root_link_imu_frame"/>
  <joint name="root_link_imu_frame_fixed_joint" type="fixed">
   <origin xyz="0.08515499999999998 -0.011000000000000022 -0.11230899999999999" rpy="-2.0943952105869323 -3.885780586188048e-16 -1.5707963267948963"/>
   <parent link="root_link"/>
   <child link="root_link_imu_frame"/>
</joint>
  <gazebo reference="root_link">
    <sensor name="root_link_imu_acc" type="imu">
      <always_on>1</always_on>
      <update_rate>400</update_rate>
      <pose>0.08515499999999998 -0.011000000000000022 -0.11230899999999999 -2.0943952105869323 -3.885780586188048e-16 -1.5707963267948963</pose>
      <plugin name="root_link_xsens_imu_plugin" filename="libgazebo_yarp_imu.so">
         <yarpConfigurationFile>model://iRonCub-Mk1_v1/iRonCub/conf/gazebo_icub_xsens_inertial.ini</yarpConfigurationFile>
      </plugin>
    </sensor>
</gazebo>
  <sensor name="root_link_imu_acc" type="accelerometer">
   <parent link="root_link"/>
   <origin rpy="-2.0943952105869323 -3.885780586188048e-16 -1.5707963267948963" xyz="0.08515499999999998 -0.011000000000000022 -0.11230899999999999"/>
</sensor>
  <gazebo reference="r_arm_ft_sensor">
  <disableFixedJointLumping>true</disableFixedJointLumping>
</gazebo>
  <gazebo reference="l_arm_ft_sensor">
  <disableFixedJointLumping>true</disableFixedJointLumping>
</gazebo>
  <gazebo reference="r_leg_ft_sensor">
  <disableFixedJointLumping>true</disableFixedJointLumping>
</gazebo>
  <gazebo reference="l_leg_ft_sensor">
  <disableFixedJointLumping>true</disableFixedJointLumping>
</gazebo>
  <gazebo reference="r_foot_ft_sensor">
  <disableFixedJointLumping>true</disableFixedJointLumping>
</gazebo>
  <gazebo reference="l_foot_ft_sensor">
  <disableFixedJointLumping>true</disableFixedJointLumping>
</gazebo>
  <gazebo reference="r_elbow_turbine">
  <disableFixedJointLumping>true</disableFixedJointLumping>
</gazebo>
  <gazebo reference="l_elbow_turbine">
  <disableFixedJointLumping>true</disableFixedJointLumping>
</gazebo>
  <gazebo reference="l_jet_turbine">
  <disableFixedJointLumping>true</disableFixedJointLumping>
</gazebo>
  <gazebo reference="r_jet_turbine">
  <disableFixedJointLumping>true</disableFixedJointLumping>
</gazebo>
  <gazebo reference="l_foot">
  <collision> <surface> <bounce>
    <restitution_coefficient>0</restitution_coefficient>
    <threshold>100000</threshold>
  </bounce> </surface> </collision>
  <maxContacts>4</maxContacts>
  <kp>18000000</kp>
  <kd>100</kd>
  <maxVel>100</maxVel>
  <minDepth>0.0001</minDepth>
  <mu1>1</mu1>
  <mu2>1</mu2>
  <fdir1>0 0 0</fdir1>
</gazebo>
  <gazebo reference="r_foot">
  <collision> <surface> <bounce>
    <restitution_coefficient>0</restitution_coefficient>
    <threshold>100000</threshold>
  </bounce> </surface> </collision>
  <maxContacts>4</maxContacts>
  <kp>18000000</kp>
  <kd>100</kd>
  <maxVel>100</maxVel>
  <minDepth>0.0001</minDepth>
  <mu1>1</mu1>
  <mu2>1</mu2>
  <fdir1>0 0 0</fdir1>
</gazebo>
  <gazebo>
<plugin name="iCub_yarp_gazebo_plugin_ACCpart" filename="libgazebo_yarp_distributedinertials.so">
  <yarpConfigurationFile>model://iRonCub-Mk1_v1/iRonCub/conf/MTB/gazebo_icub_left_leg_mtb.ini</yarpConfigurationFile>
</plugin>
<plugin name="iCub_yarp_gazebo_plugin_ACCpart" filename="libgazebo_yarp_distributedinertials.so">
  <yarpConfigurationFile>model://iRonCub-Mk1_v1/iRonCub/conf/MTB/gazebo_icub_right_leg_mtb.ini</yarpConfigurationFile>
</plugin>
<plugin name="iCub_yarp_gazebo_plugin_ACCpart" filename="libgazebo_yarp_distributedinertials.so">
  <yarpConfigurationFile>model://iRonCub-Mk1_v1/iRonCub/conf/MTB/gazebo_icub_left_arm_mtb.ini</yarpConfigurationFile>
</plugin>
<plugin name="iCub_yarp_gazebo_plugin_ACCpart" filename="libgazebo_yarp_distributedinertials.so">
  <yarpConfigurationFile>model://iRonCub-Mk1_v1/iRonCub/conf/MTB/gazebo_icub_right_arm_mtb.ini</yarpConfigurationFile>
</plugin>
<plugin name="iCub_yarp_gazebo_plugin_ACCpart" filename="libgazebo_yarp_distributedinertials.so">
  <yarpConfigurationFile>model://iRonCub-Mk1_v1/iRonCub/conf/MTB/gazebo_icub_torso_mtb.ini</yarpConfigurationFile>
</plugin>
<plugin name="controlboard_torso" filename="libgazebo_yarp_controlboard.so">
  <yarpConfigurationFile>model://iRonCub-Mk1_v1/iRonCub/conf/gazebo_icub_torso.ini</yarpConfigurationFile>
</plugin>
<plugin name="controlboard_head_without_eyes" filename="libgazebo_yarp_controlboard.so">
  <yarpConfigurationFile>model://iRonCub-Mk1_v1/iRonCub/conf/gazebo_icub_head_without_eyes.ini</yarpConfigurationFile>
</plugin>
<plugin name="controlboard_left_arm_no_hand" filename="libgazebo_yarp_controlboard.so">
  <yarpConfigurationFile>model://iRonCub-Mk1_v1/iRonCub/conf/gazebo_icub_left_arm.ini</yarpConfigurationFile>
  <initialConfiguration>-0.52 0.52 0 0.785</initialConfiguration>
</plugin>
<plugin name="controlboard_right_arm_no_hand" filename="libgazebo_yarp_controlboard.so">
  <yarpConfigurationFile>model://iRonCub-Mk1_v1/iRonCub/conf/gazebo_icub_right_arm.ini</yarpConfigurationFile>
  <initialConfiguration>-0.52 0.52 0 0.785</initialConfiguration>
</plugin>
<plugin name="controlboard_right_leg" filename="libgazebo_yarp_controlboard.so">
  <yarpConfigurationFile>model://iRonCub-Mk1_v1/iRonCub/conf/gazebo_icub_right_leg.ini</yarpConfigurationFile>
</plugin>
<plugin name="controlboard_left_leg" filename="libgazebo_yarp_controlboard.so">
  <yarpConfigurationFile>model://iRonCub-Mk1_v1/iRonCub/conf/gazebo_icub_left_leg.ini</yarpConfigurationFile>
</plugin>
<plugin name="apply_external_wrench" filename="libgazebo_yarp_externalwrench.so">
  <robotNamefromConfigFile>model://iRonCub-Mk1_v1/iRonCub/conf/gazebo_icub_robotname.ini</robotNamefromConfigFile>
</plugin>
<plugin name="basestate" filename="libgazebo_yarp_basestate.so">
  <yarpConfigurationFile>model://iRonCub-Mk1_v1/iRonCub/conf/base.ini</yarpConfigurationFile>
</plugin>
<plugin name="jets-plugin" filename="libjets-plugin-v1.so">
  <yarpConfigurationFile>model://iRonCub-Mk1_v1/iRonCub/conf/jets.ini</yarpConfigurationFile>
</plugin>
</gazebo>
  <gazebo reference="r_hip_pitch">
   <implicitSpringDamper>1</implicitSpringDamper>
</gazebo>
  <gazebo reference="r_hip_roll">
   <implicitSpringDamper>1</implicitSpringDamper>
</gazebo>
  <gazebo reference="r_hip_yaw">
   <implicitSpringDamper>1</implicitSpringDamper>
</gazebo>
  <gazebo reference="r_knee">
   <implicitSpringDamper>1</implicitSpringDamper>
</gazebo>
  <gazebo reference="r_ankle_pitch">
   <implicitSpringDamper>1</implicitSpringDamper>
</gazebo>
  <gazebo reference="r_ankle_roll">
   <implicitSpringDamper>1</implicitSpringDamper>
</gazebo>
  <gazebo reference="l_hip_pitch">
   <implicitSpringDamper>1</implicitSpringDamper>
</gazebo>
  <gazebo reference="l_hip_roll">
   <implicitSpringDamper>1</implicitSpringDamper>
</gazebo>
  <gazebo reference="l_hip_yaw">
   <implicitSpringDamper>1</implicitSpringDamper>
</gazebo>
  <gazebo reference="l_knee">
   <implicitSpringDamper>1</implicitSpringDamper>
</gazebo>
  <gazebo reference="l_ankle_pitch">
   <implicitSpringDamper>1</implicitSpringDamper>
</gazebo>
  <gazebo reference="l_ankle_roll">
   <implicitSpringDamper>1</implicitSpringDamper>
</gazebo>
  <gazebo reference="torso_pitch">
   <implicitSpringDamper>1</implicitSpringDamper>
</gazebo>
  <gazebo reference="torso_roll">
   <implicitSpringDamper>1</implicitSpringDamper>
</gazebo>
  <gazebo reference="torso_yaw">
   <implicitSpringDamper>1</implicitSpringDamper>
</gazebo>
  <gazebo reference="r_shoulder_pitch">
   <implicitSpringDamper>1</implicitSpringDamper>
</gazebo>
  <gazebo reference="r_shoulder_roll">
   <implicitSpringDamper>1</implicitSpringDamper>
</gazebo>
  <gazebo reference="r_shoulder_yaw">
   <implicitSpringDamper>1</implicitSpringDamper>
</gazebo>
  <gazebo reference="r_elbow">
   <implicitSpringDamper>1</implicitSpringDamper>
</gazebo>
  <gazebo reference="l_shoulder_pitch">
   <implicitSpringDamper>1</implicitSpringDamper>
</gazebo>
  <gazebo reference="l_shoulder_roll">
   <implicitSpringDamper>1</implicitSpringDamper>
</gazebo>
  <gazebo reference="l_shoulder_yaw">
   <implicitSpringDamper>1</implicitSpringDamper>
</gazebo>
  <gazebo reference="l_elbow">
   <implicitSpringDamper>1</implicitSpringDamper>
</gazebo>
  <gazebo reference="neck_pitch">
   <implicitSpringDamper>1</implicitSpringDamper>
</gazebo>
  <gazebo reference="neck_roll">
   <implicitSpringDamper>1</implicitSpringDamper>
</gazebo>
  <gazebo reference="neck_yaw">
   <implicitSpringDamper>1</implicitSpringDamper>
</gazebo>
  <gazebo reference="l_leg_ft_sensor">
    <sensor name="l_leg_ft_sensor" type="force_torque">
      <always_on>1</always_on>
      <update_rate>100</update_rate>
      <force_torque>
        <frame>child</frame>
        <measure_direction>child_to_parent</measure_direction>
      </force_torque>
      <pose>0.0 0.0 0.0 0.0 -0.0 0.0</pose>
      <plugin name="left_leg_ft_plugin" filename="libgazebo_yarp_forcetorque.so">
  <yarpConfigurationFile>model://iRonCub-Mk1_v1/iRonCub/conf/FT/gazebo_icub_left_leg_ft.ini</yarpConfigurationFile>
</plugin>
    </sensor>
  </gazebo>
  <sensor name="l_leg_ft_sensor" type="force_torque">
    <parent joint="l_leg_ft_sensor"/>
    <force_torque>
      <frame>child</frame>
      <measure_direction>child_to_parent</measure_direction>
    </force_torque>
    <origin rpy="0.0 -0.0 0.0" xyz="0.0 0.0 0.0"/>
  </sensor>
  <gazebo reference="r_leg_ft_sensor">
    <sensor name="r_leg_ft_sensor" type="force_torque">
      <always_on>1</always_on>
      <update_rate>100</update_rate>
      <force_torque>
        <frame>child</frame>
        <measure_direction>child_to_parent</measure_direction>
      </force_torque>
      <pose>0.0 0.0 0.0 0.0 -0.0 0.0</pose>
      <plugin name="right_leg_ft_plugin" filename="libgazebo_yarp_forcetorque.so">
  <yarpConfigurationFile>model://iRonCub-Mk1_v1/iRonCub/conf/FT/gazebo_icub_right_leg_ft.ini</yarpConfigurationFile>
</plugin>
    </sensor>
  </gazebo>
  <sensor name="r_leg_ft_sensor" type="force_torque">
    <parent joint="r_leg_ft_sensor"/>
    <force_torque>
      <frame>child</frame>
      <measure_direction>child_to_parent</measure_direction>
    </force_torque>
    <origin rpy="0.0 -0.0 0.0" xyz="0.0 0.0 0.0"/>
  </sensor>
  <gazebo reference="l_foot_ft_sensor">
    <sensor name="l_foot_ft_sensor" type="force_torque">
      <always_on>1</always_on>
      <update_rate>100</update_rate>
      <force_torque>
        <frame>child</frame>
        <measure_direction>child_to_parent</measure_direction>
      </force_torque>
      <pose>0.0 0.0 0.0 0.0 -0.0 0.0</pose>
      <plugin name="left_foot_ft_plugin" filename="libgazebo_yarp_forcetorque.so">
  <yarpConfigurationFile>model://iRonCub-Mk1_v1/iRonCub/conf/FT/gazebo_icub_left_foot_ft.ini</yarpConfigurationFile>
</plugin>
    </sensor>
  </gazebo>
  <sensor name="l_foot_ft_sensor" type="force_torque">
    <parent joint="l_foot_ft_sensor"/>
    <force_torque>
      <frame>child</frame>
      <measure_direction>child_to_parent</measure_direction>
    </force_torque>
    <origin rpy="0.0 -0.0 0.0" xyz="0.0 0.0 0.0"/>
  </sensor>
  <gazebo reference="r_foot_ft_sensor">
    <sensor name="r_foot_ft_sensor" type="force_torque">
      <always_on>1</always_on>
      <update_rate>100</update_rate>
      <force_torque>
        <frame>child</frame>
        <measure_direction>child_to_parent</measure_direction>
      </force_torque>
      <pose>0.0 0.0 0.0 0.0 -0.0 0.0</pose>
      <plugin name="right_foot_ft_plugin" filename="libgazebo_yarp_forcetorque.so">
  <yarpConfigurationFile>model://iRonCub-Mk1_v1/iRonCub/conf/FT/gazebo_icub_right_foot_ft.ini</yarpConfigurationFile>
</plugin>
    </sensor>
  </gazebo>
  <sensor name="r_foot_ft_sensor" type="force_torque">
    <parent joint="r_foot_ft_sensor"/>
    <force_torque>
      <frame>child</frame>
      <measure_direction>child_to_parent</measure_direction>
    </force_torque>
    <origin rpy="0.0 -0.0 0.0" xyz="0.0 0.0 0.0"/>
  </sensor>
  <gazebo reference="l_arm_ft_sensor">
    <sensor name="l_arm_ft_sensor" type="force_torque">
      <always_on>1</always_on>
      <update_rate>100</update_rate>
      <force_torque>
        <frame>child</frame>
        <measure_direction>child_to_parent</measure_direction>
      </force_torque>
      <pose>0.0 0.0 0.0 0.0 -0.0 0.0</pose>
      <plugin name="left_arm_ft_plugin" filename="libgazebo_yarp_forcetorque.so">
  <yarpConfigurationFile>model://iRonCub-Mk1_v1/iRonCub/conf/FT/gazebo_icub_left_arm_ft.ini</yarpConfigurationFile>
</plugin>
    </sensor>
  </gazebo>
  <sensor name="l_arm_ft_sensor" type="force_torque">
    <parent joint="l_arm_ft_sensor"/>
    <force_torque>
      <frame>child</frame>
      <measure_direction>child_to_parent</measure_direction>
    </force_torque>
    <origin rpy="0.0 -0.0 0.0" xyz="0.0 0.0 0.0"/>
  </sensor>
  <gazebo reference="r_arm_ft_sensor">
    <sensor name="r_arm_ft_sensor" type="force_torque">
      <always_on>1</always_on>
      <update_rate>100</update_rate>
      <force_torque>
        <frame>child</frame>
        <measure_direction>child_to_parent</measure_direction>
      </force_torque>
      <pose>0.0 0.0 0.0 0.0 -0.0 0.0</pose>
      <plugin name="right_arm_ft_plugin" filename="libgazebo_yarp_forcetorque.so">
  <yarpConfigurationFile>model://iRonCub-Mk1_v1/iRonCub/conf/FT/gazebo_icub_right_arm_ft.ini</yarpConfigurationFile>
</plugin>
    </sensor>
  </gazebo>
  <sensor name="r_arm_ft_sensor" type="force_torque">
    <parent joint="r_arm_ft_sensor"/>
    <force_torque>
      <frame>child</frame>
      <measure_direction>child_to_parent</measure_direction>
    </force_torque>
    <origin rpy="0.0 -0.0 0.0" xyz="0.0 0.0 0.0"/>
  </sensor>
  <gazebo reference="head">
    <sensor name="head_imu_acc_1x1" type="imu">
      <always_on>1</always_on>
      <update_rate>100</update_rate>
      <pose>0.009500000190735 0.1334431763902131 0.009300024348917928 3.141592653589793 1.5707962417722503 -1.5707963281006934</pose>
      <plugin name="iCub_yarp_gazebo_plugin_IMU" filename="libgazebo_yarp_imu.so">
    <yarpConfigurationFile>model://iRonCub-Mk1_v1/iRonCub/conf/gazebo_icub_inertial.ini</yarpConfigurationFile>
</plugin>
    </sensor>
  </gazebo>
  <sensor name="head_imu_acc_1x1" type="accelerometer">
    <parent link="head"/>
    <origin rpy="3.141592653589793 1.5707962417722503 -1.5707963281006934" xyz="0.009500000190735 0.1334431763902131 0.009300024348917928"/>
  </sensor>
  <gazebo reference="root_link">
    <sensor name="root_link_ems_acc_eb5" type="imu">
      <always_on>1</always_on>
      <update_rate>100</update_rate>
      <pose>0.0493308 -0.012577100000000023 -0.11569100000000002 -3.141592653589793 1.2915440450258353 3.141592653589793</pose>
      <plugin name="iCub_yarp_gazebo_plugin_ACC" filename="libgazebo_yarp_inertial.so"/>
    </sensor>
  </gazebo>
  <sensor name="root_link_ems_acc_eb5" type="accelerometer">
    <parent link="root_link"/>
    <origin rpy="-3.141592653589793 1.2915440450258353 3.141592653589793" xyz="0.0493308 -0.012577100000000023 -0.11569100000000002"/>
  </sensor>
  <gazebo reference="root_link">
    <sensor name="root_link_ems_gyro_eb5" type="imu">
      <always_on>1</always_on>
      <update_rate>100</update_rate>
      <pose>0.0493308 -0.012577100000000023 -0.11569100000000002 -3.141592653589793 1.2915440450258353 3.141592653589793</pose>
    </sensor>
  </gazebo>
  <sensor name="root_link_ems_gyro_eb5" type="gyroscope">
    <parent link="root_link"/>
    <origin rpy="-3.141592653589793 1.2915440450258353 3.141592653589793" xyz="0.0493308 -0.012577100000000023 -0.11569100000000002"/>
  </sensor>
  <gazebo reference="chest">
    <sensor name="chest_ems_acc_eb1" type="imu">
      <always_on>1</always_on>
      <update_rate>100</update_rate>
      <pose>0.064785500190735 0.04654319999999999 -0.06470909999999999 3.1415169122972952 -0.2617993091222473 0.0002926418802545251</pose>
      <plugin name="iCub_yarp_gazebo_plugin_ACC" filename="libgazebo_yarp_inertial.so"/>
    </sensor>
  </gazebo>
  <sensor name="chest_ems_acc_eb1" type="accelerometer">
    <parent link="chest"/>
    <origin rpy="3.1415169122972952 -0.2617993091222473 0.0002926418802545251" xyz="0.064785500190735 0.04654319999999999 -0.06470909999999999"/>
  </sensor>
  <gazebo reference="chest">
    <sensor name="chest_ems_gyro_eb1" type="imu">
      <always_on>1</always_on>
      <update_rate>100</update_rate>
      <pose>0.069201600190735 0.047048400000000004 -0.0635258 3.1415169122972952 -0.2617993091222473 0.0002926418802545251</pose>
    </sensor>
  </gazebo>
  <sensor name="chest_ems_gyro_eb1" type="gyroscope">
    <parent link="chest"/>
    <origin rpy="3.1415169122972952 -0.2617993091222473 0.0002926418802545251" xyz="0.069201600190735 0.047048400000000004 -0.0635258"/>
  </sensor>
  <gazebo reference="chest">
    <sensor name="chest_ems_acc_eb2" type="imu">
      <always_on>1</always_on>
      <update_rate>100</update_rate>
      <pose>0.020453300190735 0.070563 -0.0641645 3.141590501042822 0.2617993198185102 3.1415843367812997</pose>
      <plugin name="iCub_yarp_gazebo_plugin_ACC" filename="libgazebo_yarp_inertial.so"/>
    </sensor>
  </gazebo>
  <sensor name="chest_ems_acc_eb2" type="accelerometer">
    <parent link="chest"/>
    <origin rpy="3.141590501042822 0.2617993198185102 3.1415843367812997" xyz="0.020453300190735 0.070563 -0.0641645"/>
  </sensor>
  <gazebo reference="chest">
    <sensor name="chest_ems_gyro_eb2" type="imu">
      <always_on>1</always_on>
      <update_rate>100</update_rate>
      <pose>0.016037100190735 0.070059 -0.0653479 3.141590501042822 0.2617993198185102 3.1415843367812997</pose>
    </sensor>
  </gazebo>
  <sensor name="chest_ems_gyro_eb2" type="gyroscope">
    <parent link="chest"/>
    <origin rpy="3.141590501042822 0.2617993198185102 3.1415843367812997" xyz="0.016037100190735 0.070059 -0.0653479"/>
  </sensor>
  <gazebo reference="chest">
    <sensor name="chest_ems_acc_eb3" type="imu">
      <always_on>1</always_on>
      <update_rate>100</update_rate>
      <pose>-0.023058799809265 0.046518699999999996 -0.07589850000000001 3.141109162025268 0.2611005164711609 -0.00030907146255546275</pose>
      <plugin name="iCub_yarp_gazebo_plugin_ACC" filename="libgazebo_yarp_inertial.so"/>
    </sensor>
  </gazebo>
  <sensor name="chest_ems_acc_eb3" type="accelerometer">
    <parent link="chest"/>
    <origin rpy="3.141109162025268 0.2611005164711609 -0.00030907146255546275" xyz="-0.023058799809265 0.046518699999999996 -0.07589850000000001"/>
  </sensor>
  <gazebo reference="chest">
    <sensor name="chest_ems_gyro_eb3" type="imu">
      <always_on>1</always_on>
      <update_rate>100</update_rate>
      <pose>-0.018641699809265 0.0470213 -0.0770785 3.141109162025268 0.2611005164711609 -0.00030907146255546275</pose>
    </sensor>
  </gazebo>
  <sensor name="chest_ems_gyro_eb3" type="gyroscope">
    <parent link="chest"/>
    <origin rpy="3.141109162025268 0.2611005164711609 -0.00030907146255546275" xyz="-0.018641699809265 0.0470213 -0.0770785"/>
  </sensor>
  <gazebo reference="chest">
    <sensor name="chest_ems_acc_eb4" type="imu">
      <always_on>1</always_on>
      <update_rate>100</update_rate>
      <pose>-0.06216209980926501 0.070563 -0.0529887 -3.1415905047625503 -0.26179931981852844 3.141584339870295</pose>
      <plugin name="iCub_yarp_gazebo_plugin_ACC" filename="libgazebo_yarp_inertial.so"/>
    </sensor>
  </gazebo>
  <sensor name="chest_ems_acc_eb4" type="accelerometer">
    <parent link="chest"/>
    <origin rpy="-3.1415905047625503 -0.26179931981852844 3.141584339870295" xyz="-0.06216209980926501 0.070563 -0.0529887"/>
  </sensor>
  <gazebo reference="chest">
    <sensor name="chest_ems_gyro_eb4" type="imu">
      <always_on>1</always_on>
      <update_rate>100</update_rate>
      <pose>-0.06657839980926501 0.070059 -0.0518054 -3.1415905047625503 -0.26179931981852844 3.141584339870295</pose>
    </sensor>
  </gazebo>
  <sensor name="chest_ems_gyro_eb4" type="gyroscope">
    <parent link="chest"/>
    <origin rpy="-3.1415905047625503 -0.26179931981852844 3.141584339870295" xyz="-0.06657839980926501 0.070059 -0.0518054"/>
  </sensor>
  <gazebo reference="chest">
    <sensor name="chest_mtb_acc_0b7" type="imu">
      <always_on>1</always_on>
      <update_rate>100</update_rate>
      <pose>-0.060753799809265 -0.019284000000000003 0.044233999999999996 0.8751638289893696 0.1164020518468761 -1.4860060736169758</pose>
      <plugin name="iCub_yarp_gazebo_plugin_ACC" filename="libgazebo_yarp_inertial.so"/>
    </sensor>
  </gazebo>
  <sensor name="chest_mtb_acc_0b7" type="accelerometer">
    <parent link="chest"/>
    <origin rpy="0.8751638289893696 0.1164020518468761 -1.4860060736169758" xyz="-0.060753799809265 -0.019284000000000003 0.044233999999999996"/>
  </sensor>
  <gazebo reference="chest">
    <sensor name="chest_mtb_acc_0b8" type="imu">
      <always_on>1</always_on>
      <update_rate>100</update_rate>
      <pose>-0.045704699809265004 -0.019346900000000004 0.056742299999999996 0.5009597450656248 0.10731466950118992 -1.477834081870643</pose>
      <plugin name="iCub_yarp_gazebo_plugin_ACC" filename="libgazebo_yarp_inertial.so"/>
    </sensor>
  </gazebo>
  <sensor name="chest_mtb_acc_0b8" type="accelerometer">
    <parent link="chest"/>
    <origin rpy="0.5009597450656248 0.10731466950118992 -1.477834081870643" xyz="-0.045704699809265004 -0.019346900000000004 0.056742299999999996"/>
  </sensor>
  <gazebo reference="chest">
    <sensor name="chest_mtb_acc_0b9" type="imu">
      <always_on>1</always_on>
      <update_rate>100</update_rate>
      <pose>0.043903600190735 -0.0192848 0.0577217 -0.5009600957070279 0.10731768903025864 -1.663756285542851</pose>
      <plugin name="iCub_yarp_gazebo_plugin_ACC" filename="libgazebo_yarp_inertial.so"/>
    </sensor>
  </gazebo>
  <sensor name="chest_mtb_acc_0b9" type="accelerometer">
    <parent link="chest"/>
    <origin rpy="-0.5009600957070279 0.10731768903025864 -1.663756285542851" xyz="0.043903600190735 -0.0192848 0.0577217"/>
  </sensor>
  <gazebo reference="chest">
    <sensor name="chest_mtb_acc_0b10" type="imu">
      <always_on>1</always_on>
      <update_rate>100</update_rate>
      <pose>0.059428600190735 -0.019355000000000004 0.0457977 -0.8751681917812583 0.11635964331569845 -1.6556198765987773</pose>
      <plugin name="iCub_yarp_gazebo_plugin_ACC" filename="libgazebo_yarp_inertial.so"/>
    </sensor>
  </gazebo>
  <sensor name="chest_mtb_acc_0b10" type="accelerometer">
    <parent link="chest"/>
    <origin rpy="-0.8751681917812583 0.11635964331569845 -1.6556198765987773" xyz="0.059428600190735 -0.019355000000000004 0.0457977"/>
  </sensor>
  <gazebo reference="r_upper_arm">
    <sensor name="r_upper_arm_mtb_acc_2b10" type="imu">
      <always_on>1</always_on>
      <update_rate>100</update_rate>
      <pose>-0.0412195 0.029588000000000003 0.029527899999999985 1.5707954636460495 1.5707838122500957 -2.682571611648293</pose>
      <plugin name="iCub_yarp_gazebo_plugin_ACC" filename="libgazebo_yarp_inertial.so"/>
    </sensor>
  </gazebo>
  <sensor name="r_upper_arm_mtb_acc_2b10" type="accelerometer">
    <parent link="r_upper_arm"/>
    <origin rpy="1.5707954636460495 1.5707838122500957 -2.682571611648293" xyz="-0.0412195 0.029588000000000003 0.029527899999999985"/>
  </sensor>
  <gazebo reference="r_upper_arm">
    <sensor name="r_upper_arm_mtb_acc_2b11" type="imu">
      <always_on>1</always_on>
      <update_rate>100</update_rate>
      <pose>-0.0430561 0.028679999999999983 0.07606129999999997 -1.5707977799564055 -1.5706473391233757 0.45902335848929154</pose>
      <plugin name="iCub_yarp_gazebo_plugin_ACC" filename="libgazebo_yarp_inertial.so"/>
    </sensor>
  </gazebo>
  <sensor name="r_upper_arm_mtb_acc_2b11" type="accelerometer">
    <parent link="r_upper_arm"/>
    <origin rpy="-1.5707977799564055 -1.5706473391233757 0.45902335848929154" xyz="-0.0430561 0.028679999999999983 0.07606129999999997"/>
  </sensor>
  <gazebo reference="r_upper_arm">
    <sensor name="r_upper_arm_mtb_acc_2b12" type="imu">
      <always_on>1</always_on>
      <update_rate>100</update_rate>
      <pose>-0.043055399999999994 0.028679999999999983 0.004992199999999981 -1.1117744216835481 -1.5707963267948963 0.0</pose>
      <plugin name="iCub_yarp_gazebo_plugin_ACC" filename="libgazebo_yarp_inertial.so"/>
    </sensor>
  </gazebo>
  <sensor name="r_upper_arm_mtb_acc_2b12" type="accelerometer">
    <parent link="r_upper_arm"/>
    <origin rpy="-1.1117744216835481 -1.5707963267948963 0.0" xyz="-0.043055399999999994 0.028679999999999983 0.004992199999999981"/>
  </sensor>
  <gazebo reference="r_upper_arm">
    <sensor name="r_upper_arm_mtb_acc_2b13" type="imu">
      <always_on>1</always_on>
      <update_rate>100</update_rate>
      <pose>0.010592977999999992 0.028349999999999986 -0.0107383 1.5707963270155092 -0.00021452036204109946 2.4780367445076594</pose>
      <plugin name="iCub_yarp_gazebo_plugin_ACC" filename="libgazebo_yarp_inertial.so"/>
    </sensor>
  </gazebo>
  <sensor name="r_upper_arm_mtb_acc_2b13" type="accelerometer">
    <parent link="r_upper_arm"/>
    <origin rpy="1.5707963270155092 -0.00021452036204109946 2.4780367445076594" xyz="0.010592977999999992 0.028349999999999986 -0.0107383"/>
  </sensor>
  <gazebo reference="l_upper_arm">
    <sensor name="l_upper_arm_mtb_acc_1b10" type="imu">
      <always_on>1</always_on>
      <update_rate>100</update_rate>
      <pose>-0.04305540051672349 -0.028680000137219358 0.029527899113272936 -1.5707973843892253 -1.5705035072569904 2.682571806378897</pose>
      <plugin name="iCub_yarp_gazebo_plugin_ACC" filename="libgazebo_yarp_inertial.so"/>
    </sensor>
  </gazebo>
  <sensor name="l_upper_arm_mtb_acc_1b10" type="accelerometer">
    <parent link="l_upper_arm"/>
    <origin rpy="-1.5707973843892253 -1.5705035072569904 2.682571806378897" xyz="-0.04305540051672349 -0.028680000137219358 0.029527899113272936"/>
  </sensor>
  <gazebo reference="l_upper_arm">
    <sensor name="l_upper_arm_mtb_acc_1b11" type="imu">
      <always_on>1</always_on>
      <update_rate>100</update_rate>
      <pose>-0.04121810133101896 -0.029588000353461014 0.07606039914120519 -1.5707973843892253 -1.5705035072569904 2.682571806378897</pose>
      <plugin name="iCub_yarp_gazebo_plugin_ACC" filename="libgazebo_yarp_inertial.so"/>
    </sensor>
  </gazebo>
  <sensor name="l_upper_arm_mtb_acc_1b11" type="accelerometer">
    <parent link="l_upper_arm"/>
    <origin rpy="-1.5707973843892253 -1.5705035072569904 2.682571806378897" xyz="-0.04121810133101896 -0.029588000353461014 0.07606039914120519"/>
  </sensor>
  <gazebo reference="l_upper_arm">
    <sensor name="l_upper_arm_mtb_acc_1b12" type="imu">
      <always_on>1</always_on>
      <update_rate>100</update_rate>
      <pose>-0.04121950008735927 -0.029588000023198835 0.004992099141180699 -1.570796382569704 -1.5707838122341566 2.68257080426013</pose>
      <plugin name="iCub_yarp_gazebo_plugin_ACC" filename="libgazebo_yarp_inertial.so"/>
    </sensor>
  </gazebo>
  <sensor name="l_upper_arm_mtb_acc_1b12" type="accelerometer">
    <parent link="l_upper_arm"/>
    <origin rpy="-1.570796382569704 -1.5707838122341566 2.68257080426013" xyz="-0.04121950008735927 -0.029588000023198835 0.004992099141180699"/>
  </sensor>
  <gazebo reference="l_upper_arm">
    <sensor name="l_upper_arm_mtb_acc_1b13" type="imu">
      <always_on>1</always_on>
      <update_rate>100</update_rate>
      <pose>0.010592979152100387 -0.028349999959608713 -0.00869169994637372 -1.5707963268965792 0.0002145203878406847 -2.478036744506931</pose>
      <plugin name="iCub_yarp_gazebo_plugin_ACC" filename="libgazebo_yarp_inertial.so"/>
    </sensor>
  </gazebo>
  <sensor name="l_upper_arm_mtb_acc_1b13" type="accelerometer">
    <parent link="l_upper_arm"/>
    <origin rpy="-1.5707963268965792 0.0002145203878406847 -2.478036744506931" xyz="0.010592979152100387 -0.028349999959608713 -0.00869169994637372"/>
  </sensor>
  <gazebo reference="r_upper_leg">
    <sensor name="r_upper_leg_ems_acc_eb8" type="imu">
      <always_on>1</always_on>
      <update_rate>100</update_rate>
      <pose>-0.012575099999999999 0.04040709999999999 -0.040226999999999985 1.5707963267948972 1.5707963267948961 0.0</pose>
      <plugin name="iCub_yarp_gazebo_plugin_ACC" filename="libgazebo_yarp_inertial.so"/>
    </sensor>
  </gazebo>
  <sensor name="r_upper_leg_ems_acc_eb8" type="accelerometer">
    <parent link="r_upper_leg"/>
    <origin rpy="1.5707963267948972 1.5707963267948961 0.0" xyz="-0.012575099999999999 0.04040709999999999 -0.040226999999999985"/>
  </sensor>
  <gazebo reference="r_upper_leg">
    <sensor name="r_upper_leg_ems_acc_eb11" type="imu">
      <always_on>1</always_on>
      <update_rate>100</update_rate>
      <pose>-0.012577100000000015 -0.040406899999999996 -0.08340699999999998 1.5707963267948972 1.5707963267948961 0.0</pose>
      <plugin name="iCub_yarp_gazebo_plugin_ACC" filename="libgazebo_yarp_inertial.so"/>
    </sensor>
  </gazebo>
  <sensor name="r_upper_leg_ems_acc_eb11" type="accelerometer">
    <parent link="r_upper_leg"/>
    <origin rpy="1.5707963267948972 1.5707963267948961 0.0" xyz="-0.012577100000000015 -0.040406899999999996 -0.08340699999999998"/>
  </sensor>
  <gazebo reference="r_upper_leg">
    <sensor name="r_upper_leg_ems_gyro_eb8" type="imu">
      <always_on>1</always_on>
      <update_rate>100</update_rate>
      <pose>-0.013078999999999993 0.04040709999999999 -0.035654999999999964 1.5707963267948972 1.5707963267948961 0.0</pose>
    </sensor>
  </gazebo>
  <sensor name="r_upper_leg_ems_gyro_eb8" type="gyroscope">
    <parent link="r_upper_leg"/>
    <origin rpy="1.5707963267948972 1.5707963267948961 0.0" xyz="-0.013078999999999993 0.04040709999999999 -0.035654999999999964"/>
  </sensor>
  <gazebo reference="r_upper_leg">
    <sensor name="r_upper_leg_ems_gyro_eb11" type="imu">
      <always_on>1</always_on>
      <update_rate>100</update_rate>
      <pose>-0.013081000000000016 -0.040406899999999996 -0.087979 1.5707963267948972 1.5707963267948961 0.0</pose>
    </sensor>
  </gazebo>
  <sensor name="r_upper_leg_ems_gyro_eb11" type="gyroscope">
    <parent link="r_upper_leg"/>
    <origin rpy="1.5707963267948972 1.5707963267948961 0.0" xyz="-0.013081000000000016 -0.040406899999999996 -0.087979"/>
  </sensor>
  <gazebo reference="r_upper_leg">
    <sensor name="r_upper_leg_mtb_acc_11b1" type="imu">
      <always_on>1</always_on>
      <update_rate>100</update_rate>
      <pose>0.043588627999999977 -0.030194899999999983 0.048939999999999984 2.526708438028075 -1.5704448425270146 -0.2228738249803637</pose>
      <plugin name="iCub_yarp_gazebo_plugin_ACC" filename="libgazebo_yarp_inertial.so"/>
    </sensor>
  </gazebo>
  <sensor name="r_upper_leg_mtb_acc_11b1" type="accelerometer">
    <parent link="r_upper_leg"/>
    <origin rpy="2.526708438028075 -1.5704448425270146 -0.2228738249803637" xyz="0.043588627999999977 -0.030194899999999983 0.048939999999999984"/>
  </sensor>
  <gazebo reference="r_upper_leg">
    <sensor name="r_upper_leg_mtb_acc_11b2" type="imu">
      <always_on>1</always_on>
      <update_rate>100</update_rate>
      <pose>0.053946699999999986 -0.006406499999999982 0.03905600000000001 -3.129402120569715 -1.570381814956552 -0.2739898525693509</pose>
      <plugin name="iCub_yarp_gazebo_plugin_ACC" filename="libgazebo_yarp_inertial.so"/>
    </sensor>
  </gazebo>
  <sensor name="r_upper_leg_mtb_acc_11b2" type="accelerometer">
    <parent link="r_upper_leg"/>
    <origin rpy="-3.129402120569715 -1.570381814956552 -0.2739898525693509" xyz="0.053946699999999986 -0.006406499999999982 0.03905600000000001"/>
  </sensor>
  <gazebo reference="r_upper_leg">
    <sensor name="r_upper_leg_mtb_acc_11b3" type="imu">
      <always_on>1</always_on>
      <update_rate>100</update_rate>
      <pose>0.053831299999999985 -0.013021400000000002 0.0039859999999999896 -2.8773108545103274 -1.5703518030956078 -0.2642818239915216</pose>
      <plugin name="iCub_yarp_gazebo_plugin_ACC" filename="libgazebo_yarp_inertial.so"/>
    </sensor>
  </gazebo>
  <sensor name="r_upper_leg_mtb_acc_11b3" type="accelerometer">
    <parent link="r_upper_leg"/>
    <origin rpy="-2.8773108545103274 -1.5703518030956078 -0.2642818239915216" xyz="0.053831299999999985 -0.013021400000000002 0.0039859999999999896"/>
  </sensor>
  <gazebo reference="r_upper_leg">
    <sensor name="r_upper_leg_mtb_acc_11b4" type="imu">
      <always_on>1</always_on>
      <update_rate>100</update_rate>
      <pose>0.0322719 0.04226749999999999 -0.005044999999999994 -1.873909988092778 -1.570257713256341 -0.08085890295708932</pose>
      <plugin name="iCub_yarp_gazebo_plugin_ACC" filename="libgazebo_yarp_inertial.so"/>
    </sensor>
  </gazebo>
  <sensor name="r_upper_leg_mtb_acc_11b4" type="accelerometer">
    <parent link="r_upper_leg"/>
    <origin rpy="-1.873909988092778 -1.570257713256341 -0.08085890295708932" xyz="0.0322719 0.04226749999999999 -0.005044999999999994"/>
  </sensor>
  <gazebo reference="r_upper_leg">
    <sensor name="r_upper_leg_mtb_acc_11b5" type="imu">
      <always_on>1</always_on>
      <update_rate>100</update_rate>
      <pose>0.053831299999999985 0.016478599999999996 0.0039859999999999896 -2.8773108545103274 -1.5703518030956078 -0.2642818239915216</pose>
      <plugin name="iCub_yarp_gazebo_plugin_ACC" filename="libgazebo_yarp_inertial.so"/>
    </sensor>
  </gazebo>
  <sensor name="r_upper_leg_mtb_acc_11b5" type="accelerometer">
    <parent link="r_upper_leg"/>
    <origin rpy="-2.8773108545103274 -1.5703518030956078 -0.2642818239915216" xyz="0.053831299999999985 0.016478599999999996 0.0039859999999999896"/>
  </sensor>
  <gazebo reference="r_upper_leg">
    <sensor name="r_upper_leg_mtb_acc_11b6" type="imu">
      <always_on>1</always_on>
      <update_rate>100</update_rate>
      <pose>-0.043751799999999993 -0.015759400000000007 -0.026565000000000033 1.9541027553387757e-17 1.5703672368014803 -3.141592653589793</pose>
      <plugin name="iCub_yarp_gazebo_plugin_ACC" filename="libgazebo_yarp_inertial.so"/>
    </sensor>
  </gazebo>
  <sensor name="r_upper_leg_mtb_acc_11b6" type="accelerometer">
    <parent link="r_upper_leg"/>
    <origin rpy="1.9541027553387757e-17 1.5703672368014803 -3.141592653589793" xyz="-0.043751799999999993 -0.015759400000000007 -0.026565000000000033"/>
  </sensor>
  <gazebo reference="r_upper_leg">
    <sensor name="r_upper_leg_mtb_acc_11b7" type="imu">
      <always_on>1</always_on>
      <update_rate>100</update_rate>
      <pose>-0.04375179999999998 0.016238599999999992 -0.026566000000000006 0.26425252390070647 1.5703518066171935 -2.8773401047797322</pose>
      <plugin name="iCub_yarp_gazebo_plugin_ACC" filename="libgazebo_yarp_inertial.so"/>
    </sensor>
  </gazebo>
  <sensor name="r_upper_leg_mtb_acc_11b7" type="accelerometer">
    <parent link="r_upper_leg"/>
    <origin rpy="0.26425252390070647 1.5703518066171935 -2.8773401047797322" xyz="-0.04375179999999998 0.016238599999999992 -0.026566000000000006"/>
  </sensor>
  <gazebo reference="r_lower_leg">
    <sensor name="r_lower_leg_ems_acc_eb9" type="imu">
      <always_on>1</always_on>
      <update_rate>100</update_rate>
      <pose>0.04351374599999999 0.01383959999999998 -0.09276499999999999 -3.1415926535897922 -1.3526297834539558 -8.476849710455595e-16</pose>
      <plugin name="iCub_yarp_gazebo_plugin_ACC" filename="libgazebo_yarp_inertial.so"/>
    </sensor>
  </gazebo>
  <sensor name="r_lower_leg_ems_acc_eb9" type="accelerometer">
    <parent link="r_lower_leg"/>
    <origin rpy="-3.1415926535897922 -1.3526297834539558 -8.476849710455595e-16" xyz="0.04351374599999999 0.01383959999999998 -0.09276499999999999"/>
  </sensor>
  <gazebo reference="r_lower_leg">
    <sensor name="r_lower_leg_ems_gyro_eb9" type="imu">
      <always_on>1</always_on>
      <update_rate>100</update_rate>
      <pose>0.04450330799999999 0.014343499999999974 -0.08830099999999996 -3.1415926535897922 -1.3526297834539558 -8.476849710455595e-16</pose>
    </sensor>
  </gazebo>
  <sensor name="r_lower_leg_ems_gyro_eb9" type="gyroscope">
    <parent link="r_lower_leg"/>
    <origin rpy="-3.1415926535897922 -1.3526297834539558 -8.476849710455595e-16" xyz="0.04450330799999999 0.014343499999999974 -0.08830099999999996"/>
  </sensor>
  <gazebo reference="r_lower_leg">
    <sensor name="r_lower_leg_mtb_acc_11b8" type="imu">
      <always_on>1</always_on>
      <update_rate>100</update_rate>
      <pose>0.05362923999999998 -0.015195799999999995 -0.0043179999999999885 -1.5707969943117426 -1.5706802100981876 -1.8151418254260296</pose>
      <plugin name="iCub_yarp_gazebo_plugin_ACC" filename="libgazebo_yarp_inertial.so"/>
    </sensor>
  </gazebo>
  <sensor name="r_lower_leg_mtb_acc_11b8" type="accelerometer">
    <parent link="r_lower_leg"/>
    <origin rpy="-1.5707969943117426 -1.5706802100981876 -1.8151418254260296" xyz="0.05362923999999998 -0.015195799999999995 -0.0043179999999999885"/>
  </sensor>
  <gazebo reference="r_lower_leg">
    <sensor name="r_lower_leg_mtb_acc_11b9" type="imu">
      <always_on>1</always_on>
      <update_rate>100</update_rate>
      <pose>0.05375166999999999 0.01572289999999999 -0.0043179999999999885 -1.5707962918857017 -1.5706802104434696 -1.2217307214946516</pose>
      <plugin name="iCub_yarp_gazebo_plugin_ACC" filename="libgazebo_yarp_inertial.so"/>
    </sensor>
  </gazebo>
  <sensor name="r_lower_leg_mtb_acc_11b9" type="accelerometer">
    <parent link="r_lower_leg"/>
    <origin rpy="-1.5707962918857017 -1.5706802104434696 -1.2217307214946516" xyz="0.05375166999999999 0.01572289999999999 -0.0043179999999999885"/>
  </sensor>
  <gazebo reference="r_lower_leg">
    <sensor name="r_lower_leg_mtb_acc_11b10" type="imu">
      <always_on>1</always_on>
      <update_rate>100</update_rate>
      <pose>0.027894499999999982 -0.0422139 -0.04346800000000001 1.8325955062747417 -1.5707963267948963 0.0</pose>
      <plugin name="iCub_yarp_gazebo_plugin_ACC" filename="libgazebo_yarp_inertial.so"/>
    </sensor>
  </gazebo>
  <sensor name="r_lower_leg_mtb_acc_11b10" type="accelerometer">
    <parent link="r_lower_leg"/>
    <origin rpy="1.8325955062747417 -1.5707963267948963 0.0" xyz="0.027894499999999982 -0.0422139 -0.04346800000000001"/>
  </sensor>
  <gazebo reference="r_lower_leg">
    <sensor name="r_lower_leg_mtb_acc_11b11" type="imu">
      <always_on>1</always_on>
      <update_rate>100</update_rate>
      <pose>0.0164801 0.04224899999999997 -0.09295800000000004 -1.5707936954714847 -1.5706802103471817 -0.26180181049562956</pose>
      <plugin name="iCub_yarp_gazebo_plugin_ACC" filename="libgazebo_yarp_inertial.so"/>
    </sensor>
  </gazebo>
  <sensor name="r_lower_leg_mtb_acc_11b11" type="accelerometer">
    <parent link="r_lower_leg"/>
    <origin rpy="-1.5707936954714847 -1.5706802103471817 -0.26180181049562956" xyz="0.0164801 0.04224899999999997 -0.09295800000000004"/>
  </sensor>
  <gazebo reference="r_foot">
    <sensor name="r_foot_mtb_acc_11b12" type="imu">
      <always_on>1</always_on>
      <update_rate>100</update_rate>
      <pose>0.10347939999999997 -0.000812199999999999 -0.001214999999999966 1.4648752297108978e-16 2.2204452113283224e-16 -1.5707960430308967</pose>
      <plugin name="iCub_yarp_gazebo_plugin_ACC" filename="libgazebo_yarp_inertial.so"/>
    </sensor>
  </gazebo>
  <sensor name="r_foot_mtb_acc_11b12" type="accelerometer">
    <parent link="r_foot"/>
    <origin rpy="1.4648752297108978e-16 2.2204452113283224e-16 -1.5707960430308967" xyz="0.10347939999999997 -0.000812199999999999 -0.001214999999999966"/>
  </sensor>
  <gazebo reference="r_foot">
    <sensor name="r_foot_mtb_acc_11b13" type="imu">
      <always_on>1</always_on>
      <update_rate>100</update_rate>
      <pose>0.07847939999999999 -0.011812200000000009 -0.001214999999999966 2.220446049250314e-16 2.220446049250313e-16 -1.5707963267948966</pose>
      <plugin name="iCub_yarp_gazebo_plugin_ACC" filename="libgazebo_yarp_inertial.so"/>
    </sensor>
  </gazebo>
  <sensor name="r_foot_mtb_acc_11b13" type="accelerometer">
    <parent link="r_foot"/>
    <origin rpy="2.220446049250314e-16 2.220446049250313e-16 -1.5707963267948966" xyz="0.07847939999999999 -0.011812200000000009 -0.001214999999999966"/>
  </sensor>
  <gazebo reference="l_upper_leg">
    <sensor name="l_upper_leg_ems_acc_eb6" type="imu">
      <always_on>1</always_on>
      <update_rate>100</update_rate>
      <pose>-0.012577000000000012 -0.04040720000000002 -0.08340699999999998 1.5707963267948972 1.5707963267948961 0.0</pose>
      <plugin name="iCub_yarp_gazebo_plugin_ACC" filename="libgazebo_yarp_inertial.so"/>
    </sensor>
  </gazebo>
  <sensor name="l_upper_leg_ems_acc_eb6" type="accelerometer">
    <parent link="l_upper_leg"/>
    <origin rpy="1.5707963267948972 1.5707963267948961 0.0" xyz="-0.012577000000000012 -0.04040720000000002 -0.08340699999999998"/>
  </sensor>
  <gazebo reference="l_upper_leg">
    <sensor name="l_upper_leg_ems_acc_eb10" type="imu">
      <always_on>1</always_on>
      <update_rate>100</update_rate>
      <pose>-0.012575000000000003 0.04040679999999998 -0.040226999999999985 -1.5707963267948968 -1.5707963267948963 0.0</pose>
      <plugin name="iCub_yarp_gazebo_plugin_ACC" filename="libgazebo_yarp_inertial.so"/>
    </sensor>
  </gazebo>
  <sensor name="l_upper_leg_ems_acc_eb10" type="accelerometer">
    <parent link="l_upper_leg"/>
    <origin rpy="-1.5707963267948968 -1.5707963267948963 0.0" xyz="-0.012575000000000003 0.04040679999999998 -0.040226999999999985"/>
  </sensor>
  <gazebo reference="l_upper_leg">
    <sensor name="l_upper_leg_ems_gyro_eb6" type="imu">
      <always_on>1</always_on>
      <update_rate>100</update_rate>
      <pose>-0.013081000000000016 -0.04040720000000002 -0.087979 1.5707963267948972 1.5707963267948961 0.0</pose>
    </sensor>
  </gazebo>
  <sensor name="l_upper_leg_ems_gyro_eb6" type="gyroscope">
    <parent link="l_upper_leg"/>
    <origin rpy="1.5707963267948972 1.5707963267948961 0.0" xyz="-0.013081000000000016 -0.04040720000000002 -0.087979"/>
  </sensor>
  <gazebo reference="l_upper_leg">
    <sensor name="l_upper_leg_ems_gyro_eb10" type="imu">
      <always_on>1</always_on>
      <update_rate>100</update_rate>
      <pose>-0.013079 0.04040679999999998 -0.035654999999999964 -1.5707963267948968 -1.5707963267948963 0.0</pose>
    </sensor>
  </gazebo>
  <sensor name="l_upper_leg_ems_gyro_eb10" type="gyroscope">
    <parent link="l_upper_leg"/>
    <origin rpy="-1.5707963267948968 -1.5707963267948963 0.0" xyz="-0.013079 0.04040679999999998 -0.035654999999999964"/>
  </sensor>
  <gazebo reference="l_upper_leg">
    <sensor name="l_upper_leg_mtb_acc_10b1" type="imu">
      <always_on>1</always_on>
      <update_rate>100</update_rate>
      <pose>0.042001689999999994 0.03156479999999999 0.04913199999999998 -1.5707955185655114 -1.5706802103355728 -0.7330390947129777</pose>
      <plugin name="iCub_yarp_gazebo_plugin_ACC" filename="libgazebo_yarp_inertial.so"/>
    </sensor>
  </gazebo>
  <sensor name="l_upper_leg_mtb_acc_10b1" type="accelerometer">
    <parent link="l_upper_leg"/>
    <origin rpy="-1.5707955185655114 -1.5706802103355728 -0.7330390947129777" xyz="0.042001689999999994 0.03156479999999999 0.04913199999999998"/>
  </sensor>
  <gazebo reference="l_upper_leg">
    <sensor name="l_upper_leg_mtb_acc_10b2" type="imu">
      <always_on>1</always_on>
      <update_rate>100</update_rate>
      <pose>0.05352114999999998 0.007765700000000014 0.03925200000000001 -1.5707963863768455 -1.5706802103927162 -1.3089969473954748</pose>
      <plugin name="iCub_yarp_gazebo_plugin_ACC" filename="libgazebo_yarp_inertial.so"/>
    </sensor>
  </gazebo>
  <sensor name="l_upper_leg_mtb_acc_10b2" type="accelerometer">
    <parent link="l_upper_leg"/>
    <origin rpy="-1.5707963863768455 -1.5706802103927162 -1.3089969473954748" xyz="0.05352114999999998 0.007765700000000014 0.03925200000000001"/>
  </sensor>
  <gazebo reference="l_upper_leg">
    <sensor name="l_upper_leg_mtb_acc_10b3" type="imu">
      <always_on>1</always_on>
      <update_rate>100</update_rate>
      <pose>0.053784999999999986 0.015070600000000003 0.0041819999999999635 3.141592653589793 -1.5707963267948961 0.0</pose>
      <plugin name="iCub_yarp_gazebo_plugin_ACC" filename="libgazebo_yarp_inertial.so"/>
    </sensor>
  </gazebo>
  <sensor name="l_upper_leg_mtb_acc_10b3" type="accelerometer">
    <parent link="l_upper_leg"/>
    <origin rpy="3.141592653589793 -1.5707963267948961 0.0" xyz="0.053784999999999986 0.015070600000000003 0.0041819999999999635"/>
  </sensor>
  <gazebo reference="l_upper_leg">
    <sensor name="l_upper_leg_mtb_acc_10b4" type="imu">
      <always_on>1</always_on>
      <update_rate>100</update_rate>
      <pose>0.05378499999999998 -0.014429400000000002 0.0041819999999999635 3.141592653589793 -1.5707963267948961 0.0</pose>
      <plugin name="iCub_yarp_gazebo_plugin_ACC" filename="libgazebo_yarp_inertial.so"/>
    </sensor>
  </gazebo>
  <sensor name="l_upper_leg_mtb_acc_10b4" type="accelerometer">
    <parent link="l_upper_leg"/>
    <origin rpy="3.141592653589793 -1.5707963267948961 0.0" xyz="0.05378499999999998 -0.014429400000000002 0.0041819999999999635"/>
  </sensor>
  <gazebo reference="l_upper_leg">
    <sensor name="l_upper_leg_mtb_acc_10b5" type="imu">
      <always_on>1</always_on>
      <update_rate>100</update_rate>
      <pose>0.03412954999999998 -0.0414999 -0.004858000000000029 1.9547688910448342 -1.5707963267948961 0.0</pose>
      <plugin name="iCub_yarp_gazebo_plugin_ACC" filename="libgazebo_yarp_inertial.so"/>
    </sensor>
  </gazebo>
  <sensor name="l_upper_leg_mtb_acc_10b5" type="accelerometer">
    <parent link="l_upper_leg"/>
    <origin rpy="1.9547688910448342 -1.5707963267948961 0.0" xyz="0.03412954999999998 -0.0414999 -0.004858000000000029"/>
  </sensor>
  <gazebo reference="l_upper_leg">
    <sensor name="l_upper_leg_mtb_acc_10b6" type="imu">
      <always_on>1</always_on>
      <update_rate>100</update_rate>
      <pose>-0.043785 0.017810999999999994 -0.02641099999999999 -1.5707963267919405 1.5707743139371833 1.570796326789853</pose>
      <plugin name="iCub_yarp_gazebo_plugin_ACC" filename="libgazebo_yarp_inertial.so"/>
    </sensor>
  </gazebo>
  <sensor name="l_upper_leg_mtb_acc_10b6" type="accelerometer">
    <parent link="l_upper_leg"/>
    <origin rpy="-1.5707963267919405 1.5707743139371833 1.570796326789853" xyz="-0.043785 0.017810999999999994 -0.02641099999999999"/>
  </sensor>
  <gazebo reference="l_upper_leg">
    <sensor name="l_upper_leg_mtb_acc_10b7" type="imu">
      <always_on>1</always_on>
      <update_rate>100</update_rate>
      <pose>-0.04378500000000001 -0.014191800000000011 -0.02641099999999999 1.5707963267982468 1.5706473388946958 -1.5707963267919158</pose>
      <plugin name="iCub_yarp_gazebo_plugin_ACC" filename="libgazebo_yarp_inertial.so"/>
    </sensor>
  </gazebo>
  <sensor name="l_upper_leg_mtb_acc_10b7" type="accelerometer">
    <parent link="l_upper_leg"/>
    <origin rpy="1.5707963267982468 1.5706473388946958 -1.5707963267919158" xyz="-0.04378500000000001 -0.014191800000000011 -0.02641099999999999"/>
  </sensor>
  <gazebo reference="l_lower_leg">
    <sensor name="l_lower_leg_ems_acc_eb7" type="imu">
      <always_on>1</always_on>
      <update_rate>100</update_rate>
      <pose>0.04351379199999999 0.011314499999999963 -0.09276499999999999 -3.1415926535897922 -1.3526297834539558 -8.476849710455595e-16</pose>
      <plugin name="iCub_yarp_gazebo_plugin_ACC" filename="libgazebo_yarp_inertial.so"/>
    </sensor>
  </gazebo>
  <sensor name="l_lower_leg_ems_acc_eb7" type="accelerometer">
    <parent link="l_lower_leg"/>
    <origin rpy="-3.1415926535897922 -1.3526297834539558 -8.476849710455595e-16" xyz="0.04351379199999999 0.011314499999999963 -0.09276499999999999"/>
  </sensor>
  <gazebo reference="l_lower_leg">
    <sensor name="l_lower_leg_ems_gyro_eb7" type="imu">
      <always_on>1</always_on>
      <update_rate>100</update_rate>
      <pose>0.04450335399999999 0.011818499999999968 -0.08830099999999996 -3.1415926535897922 -1.3526297834539558 -8.476849710455595e-16</pose>
    </sensor>
  </gazebo>
  <sensor name="l_lower_leg_ems_gyro_eb7" type="gyroscope">
    <parent link="l_lower_leg"/>
    <origin rpy="-3.1415926535897922 -1.3526297834539558 -8.476849710455595e-16" xyz="0.04450335399999999 0.011818499999999968 -0.08830099999999996"/>
  </sensor>
  <gazebo reference="l_lower_leg">
    <sensor name="l_lower_leg_mtb_acc_10b8" type="imu">
      <always_on>1</always_on>
      <update_rate>100</update_rate>
      <pose>0.053133529999999984 0.017184099999999994 -0.0043179999999999885 -2.8972464875193467 -1.5707963267948963 0.0</pose>
      <plugin name="iCub_yarp_gazebo_plugin_ACC" filename="libgazebo_yarp_inertial.so"/>
    </sensor>
  </gazebo>
  <sensor name="l_lower_leg_mtb_acc_10b8" type="accelerometer">
    <parent link="l_lower_leg"/>
    <origin rpy="-2.8972464875193467 -1.5707963267948963 0.0" xyz="0.053133529999999984 0.017184099999999994 -0.0043179999999999885"/>
  </sensor>
  <gazebo reference="l_lower_leg">
    <sensor name="l_lower_leg_mtb_acc_10b9" type="imu">
      <always_on>1</always_on>
      <update_rate>100</update_rate>
      <pose>0.054451899999999984 -0.013799100000000009 -0.0043179999999999885 -1.5707963664504991 -1.5706802104435666 -1.919861927351539</pose>
      <plugin name="iCub_yarp_gazebo_plugin_ACC" filename="libgazebo_yarp_inertial.so"/>
    </sensor>
  </gazebo>
  <sensor name="l_lower_leg_mtb_acc_10b9" type="accelerometer">
    <parent link="l_lower_leg"/>
    <origin rpy="-1.5707963664504991 -1.5706802104435666 -1.919861927351539" xyz="0.054451899999999984 -0.013799100000000009 -0.0043179999999999885"/>
  </sensor>
  <gazebo reference="l_lower_leg">
    <sensor name="l_lower_leg_mtb_acc_10b10" type="imu">
      <always_on>1</always_on>
      <update_rate>100</update_rate>
      <pose>0.025915199999999996 0.04274479999999997 -0.04346800000000001 -1.5707936954714847 -1.5706802103471817 -0.26180181049562956</pose>
      <plugin name="iCub_yarp_gazebo_plugin_ACC" filename="libgazebo_yarp_inertial.so"/>
    </sensor>
  </gazebo>
  <sensor name="l_lower_leg_mtb_acc_10b10" type="accelerometer">
    <parent link="l_lower_leg"/>
    <origin rpy="-1.5707936954714847 -1.5706802103471817 -0.26180181049562956" xyz="0.025915199999999996 0.04274479999999997 -0.04346800000000001"/>
  </sensor>
  <gazebo reference="l_lower_leg">
    <sensor name="l_lower_leg_mtb_acc_10b11" type="imu">
      <always_on>1</always_on>
      <update_rate>100</update_rate>
      <pose>0.018459299999999977 -0.041718700000000025 -0.09295800000000004 1.5707953192782331 -1.5707699978643246 0.26180018702487956</pose>
      <plugin name="iCub_yarp_gazebo_plugin_ACC" filename="libgazebo_yarp_inertial.so"/>
    </sensor>
  </gazebo>
  <sensor name="l_lower_leg_mtb_acc_10b11" type="accelerometer">
    <parent link="l_lower_leg"/>
    <origin rpy="1.5707953192782331 -1.5707699978643246 0.26180018702487956" xyz="0.018459299999999977 -0.041718700000000025 -0.09295800000000004"/>
  </sensor>
  <gazebo reference="l_foot">
    <sensor name="l_foot_mtb_acc_10b12" type="imu">
      <always_on>1</always_on>
      <update_rate>100</update_rate>
      <pose>0.10552739999999997 0.0008122000000000129 -0.001214999999999966 0.0 -0.0 1.5707963267948966</pose>
      <plugin name="iCub_yarp_gazebo_plugin_ACC" filename="libgazebo_yarp_inertial.so"/>
    </sensor>
  </gazebo>
  <sensor name="l_foot_mtb_acc_10b12" type="accelerometer">
    <parent link="l_foot"/>
    <origin rpy="0.0 -0.0 1.5707963267948966" xyz="0.10552739999999997 0.0008122000000000129 -0.001214999999999966"/>
  </sensor>
  <gazebo reference="l_foot">
    <sensor name="l_foot_mtb_acc_10b13" type="imu">
      <always_on>1</always_on>
      <update_rate>100</update_rate>
      <pose>0.08052739999999997 0.011812200000000002 -0.001214999999999966 0.0 -0.0 1.5707963267948966</pose>
      <plugin name="iCub_yarp_gazebo_plugin_ACC" filename="libgazebo_yarp_inertial.so"/>
    </sensor>
  </gazebo>
  <sensor name="l_foot_mtb_acc_10b13" type="accelerometer">
    <parent link="l_foot"/>
    <origin rpy="0.0 -0.0 1.5707963267948966" xyz="0.08052739999999997 0.011812200000000002 -0.001214999999999966"/>
  </sensor>
  <gazebo>
    <pose>0.0 0.0 0.63 0.0 0.0 3.14</pose>
  </gazebo>
</robot>
